Workbook

Sheet Utah Roster and Grades
A1: Offense Two Deep
A4: WR-X | I4: Left Tackle | L4: Left Guard | O4: Center | R4: Right Guard | U4: Right Tackle | AB4: WR-Z
X5: Tight End
A6: Tobias Merriweather | C6: 4.01 | I6: Caleb Lomu | K6: 5.21 | L6: Tanoa Togiai | N6: 4.51 | O6: Jaren Kump | Q6: 4.24 | R6: Michael Mokofisi | T6: 4.97 | U6: Spencer Fano | W6: 5.46 | AB6: Ryan Davis | AD6: 3.76
A7: Creed Whittmore | C7: 4.03 | E7: WR-Slot | I7: Zereoue Williams | L7: Reece Parenter | O7: Alex Harrison | R7: Keith Olson | U7: Isaiah Garcia | X7: Dallen Bentley | Z7: 4.54 | AB7: Larry Simmons | AD7: 4.4
X8: Lander Barton
E9: JJ Buchanan | G9: 3.79
E10: Smith Snowden | O10: Quarterback | S10: Running Back
O12: Devon Dampier | Q12: 4.57 | S12: Wayshawn Parker | U12: 4.96
O13: Byrd Ficklin | Q13: 4.54 | S13: NaQuari Rogers | U13: 4.05
O14: Isaac Wilson | S14: Bryce Duke
S15: Daniel Bray | U15: 4.43
A18: Defense Two Deep
A21: CB | I21: Left Defensive End | M21: Left Defensive Tackle | Q21: Right Defensive Tackle | U21: Right Defensive End | AB21: CB
A23: Blake Cotton | C23: 4.7 | I23: Logan Fano | M23: Jonah Lea'ea | Q23: Aliki Vimahi | U23: John Henry Daley | AB23: Elijah Davis
A24: Don Saunders | E24: Nickel CB | I24: Kash Dillon | M24: Pupu Sepulona | Q24: Karson Kaufusi | U24: Lance Holtzclaw | AB24: JC Hart
E26: Smith Snowden
E27: LaTristan Thompson | L27: WILL LB | Q27: MIKE LB
L29: Johnathan Hall | Q29: Trey Reynolds
L30: Levani Damuni | Q30: Cyrus Polu
J36: Free Safety | R36: Strong Safety
J38: Jackson Bennee | R38: Tao Johnson
J39: Nate Tilmon | R39: Nate Ritchie
J40: Ashton Olevao | R40: Rabbit Evans

Sheet QB Sheet
A1: Name | B1: Team | C1: # | D1: POS | E1: CONF | F1: DB | G1: ATT | H1: COMP | I1: COMP% | J1: PASS YDS | K1: PASS YPA | L1: PASS TD | M1: INT | N1: SK | O1: TWP | P1: Game Score | Q1: Normalized Game Score | S1: Game Score | T1: Average Value | U1: Film Grade | V1: Differential | W1: Conference Modifier | X1: Adjusted Game Score | Y1: Normalized Adjusted Game Score | Z1: Differential | AB1: FCS Prospect Percentile | AC1: G5 Prospect Percentile | AD1: P4 Prospect Percentile
A2: Brendan Sorsby | B2: Team | C2: 2 | D2: QB | E2: Big 12 | F2: 400 | G2: 357 | H2: 213 | I2: 0.597 | J2: 2906 | K2: 8.1 | L2: 26 | M2: 5 | N2: 7 | O2: 7 | P2: =IFERROR((I2*0.35+K2*7+L2*6+J2/25-M2*10-(N2/F2)*50-(O2/G2)*40)/50,0) -> 5.5497927 | Q2: =100*(P2-MIN($P$2:$P$692))/(MAX($P$2:$P$692) - MIN($P$2:$P$692)) -> 3.0307514 | S2: 5.5497927 | T2: 1.01 | U2: 5.49 | V2: 3.5 | W2: 1 | X2: =IFERROR((U2*0.7+T2*0.15+S2*0.15*W7),0) -> 4.743722 | Y2: =100*(X2-MIN($X$2:$X$692))/(MAX($X$2:$X$692) - MIN($X$2:$X$692)) -> 95.356812 | Z2: =Y2-Q2 -> 92.32606 | AB2: =IFERROR(__xludf.DUMMYFUNCTION("iferror(PERCENTRANK.INC(FILTER($X$2:$X$423, $U$2:$U$423<3.75), $X2), 1)"),1.0) -> 1 | AC2: =IFERROR(__xludf.DUMMYFUNCTION("iferror(PERCENTRANK.INC(FILTER($X$2:$X$423, $U$2:$U$423<4.25), $X2), 1)"),1.0) -> 1 | AD2: =IFERROR(__xludf.DUMMYFUNCTION("iferror(PERCENTRANK.INC(FILTER($X$2:$X$423, $U$2:$U$423>=4.1), $X2), 0.01)"),0.92) -> 0.92
A3: Jaden Craig | B3: HARVARD | C3: 1 | D3: QB | E3: Ivy | F3: 398 | G3: 359 | H3: 212 | I3: 0.591 | J3: 2887 | K3: 8 | L3: 25 | M3: 7 | N3: 13 | O3: 12 | P3: =IFERROR((I3*0.35+K3*7+L3*6+J3/25-M3*10-(N3/F3)*50-(O3/G3)*40)/50,0) -> 4.9743327 | Q3: =100*(P3-MIN($P$2:$P$692))/(MAX($P$2:$P$692) - MIN($P$2:$P$692)) -> 2.7578683 | S3: 4.9743327 | T3: 1.41 | U3: 5.19 | V3: 8.24 | W3: 0.9 | X3: =IFERROR((U3*0.7+T3*0.15+S3*0.15*W8),0) -> 4.5533424 | Y3: =100*(X3-MIN($X$2:$X$692))/(MAX($X$2:$X$692) - MIN($X$2:$X$692)) -> 93.002756 | Z3: =Y3-Q3 -> 90.244888 | AB3: =IFERROR(__xludf.DUMMYFUNCTION("iferror(PERCENTRANK.INC(FILTER($X$2:$X$423, $U$2:$U$423<3.75), $X3), 1)"),1.0) -> 1 | AC3: =IFERROR(__xludf.DUMMYFUNCTION("iferror(PERCENTRANK.INC(FILTER($X$2:$X$423, $U$2:$U$423<4.25), $X3), 1)"),1.0) -> 1 | AD3: =IFERROR(__xludf.DUMMYFUNCTION("iferror(PERCENTRANK.INC(FILTER($X$2:$X$423, $U$2:$U$423>=4.1), $X3), 0.01)"),0.88) -> 0.88
A4: Jax Leatherwood | B4: SE MO ST | C4: 12 | D4: QB | E4: Big South - OVC Football Association | F4: 335 | G4: 291 | H4: 176 | I4: 0.605 | J4: 1969 | K4: 6.8 | L4: 12 | M4: 2 | N4: 27 | O4: 6 | P4: =IFERROR((I4*0.35+K4*7+L4*6+J4/25-M4*10-(N4/F4)*50-(O4/G4)*40)/50,0) -> 3.4743431 | Q4: =100*(P4-MIN($P$2:$P$692))/(MAX($P$2:$P$692) - MIN($P$2:$P$692)) -> 2.0465733 | S4: 3.4743431 | T4: 3.59 | U4: 4.8 | V4: 16.75 | W4: 0.9 | X4: =IFERROR((U4*0.7+T4*0.15+S4*0.15*W9),0) -> 4.4196515 | Y4: =100*(X4-MIN($X$2:$X$692))/(MAX($X$2:$X$692) - MIN($X$2:$X$692)) -> 91.349659 | Z4: =Y4-Q4 -> 89.303086 | AB4: =IFERROR(__xludf.DUMMYFUNCTION("iferror(PERCENTRANK.INC(FILTER($X$2:$X$423, $U$2:$U$423<3.75), $X4), 1)"),1.0) -> 1 | AC4: =IFERROR(__xludf.DUMMYFUNCTION("iferror(PERCENTRANK.INC(FILTER($X$2:$X$423, $U$2:$U$423<4.25), $X4), 1)"),1.0) -> 1 | AD4: =IFERROR(__xludf.DUMMYFUNCTION("iferror(PERCENTRANK.INC(FILTER($X$2:$X$423, $U$2:$U$423>=4.1), $X4), 0.01)"),0.84) -> 0.84
A5: Dylan Raiola | B5: NEBRASKA | C5: 15 | D5: QB | E5: Big Ten | F5: 305 | G5: 261 | H5: 185 | I5: 0.709 | J5: 2039 | K5: 7.8 | L5: 18 | M5: 6 | N5: 28 | O5: 11 | P5: =IFERROR((I5*0.35+K5*7+L5*6+J5/25-M5*10-(N5/F5)*50-(O5/G5)*40)/50,0) -> 3.5626432 | Q5: =100*(P5-MIN($P$2:$P$692))/(MAX($P$2:$P$692) - MIN($P$2:$P$692)) -> 2.0884452 | S5: 3.5626432 | T5: 1 | U5: 5.36 | V5: 7.6 | W5: 1 | X5: =IFERROR((U5*0.7+T5*0.15+S5*0.15*W10),0) -> 4.3829568 | Y5: =100*(X5-MIN($X$2:$X$692))/(MAX($X$2:$X$692) - MIN($X$2:$X$692)) -> 90.895928 | Z5: =Y5-Q5 -> 88.807482 | AB5: =IFERROR(__xludf.DUMMYFUNCTION("iferror(PERCENTRANK.INC(FILTER($X$2:$X$423, $U$2:$U$423<3.75), $X5), 1)"),1.0) -> 1 | AC5: =IFERROR(__xludf.DUMMYFUNCTION("iferror(PERCENTRANK.INC(FILTER($X$2:$X$423, $U$2:$U$423<4.25), $X5), 1)"),1.0) -> 1 | AD5: =IFERROR(__xludf.DUMMYFUNCTION("iferror(PERCENTRANK.INC(FILTER($X$2:$X$423, $U$2:$U$423>=4.1), $X5), 0.01)"),0.8) -> 0.8
A6: Wyatt Bower | B6: FERRIS ST | C6: 2 | D6: QB | E6: Ferris State | F6: 185 | G6: 185 | H6: 114 | I6: 0.616 | J6: 1709 | K6: 9.2 | L6: 18 | M6: 4 | N6: 3 | O6: 3 | P6: =IFERROR((I6*0.35+K6*7+L6*6+J6/25-M6*10-(N6/F6)*50-(O6/G6)*40)/50,0) -> 3.9903228 | Q6: =100*(P6-MIN($P$2:$P$692))/(MAX($P$2:$P$692) - MIN($P$2:$P$692)) -> 2.2912508 | S6: 3.9903228 | T6: 3 | U6: 4.36 | V6: -4.99 | W6: 0.85 | X6: =IFERROR((U6*0.7+T6*0.15+S6*0.15*W11),0) -> 4.0406936 | Y6: =100*(X6-MIN($X$2:$X$692))/(MAX($X$2:$X$692) - MIN($X$2:$X$692)) -> 86.663821 | Z6: =Y6-Q6 -> 84.37257 | AB6: =IFERROR(__xludf.DUMMYFUNCTION("iferror(PERCENTRANK.INC(FILTER($X$2:$X$423, $U$2:$U$423<3.75), $X6), 1)"),0.997) -> 0.997 | AC6: =IFERROR(__xludf.DUMMYFUNCTION("iferror(PERCENTRANK.INC(FILTER($X$2:$X$423, $U$2:$U$423<4.25), $X6), 1)"),0.996) -> 0.996 | AD6: =IFERROR(__xludf.DUMMYFUNCTION("iferror(PERCENTRANK.INC(FILTER($X$2:$X$423, $U$2:$U$423>=4.1), $X6), 0.01)"),0.76) -> 0.76
A7: Ean Rodrigue | B7: NICHOLLS | C7: 11 | D7: QB | E7: Southland | F7: 158 | G7: 137 | H7: 89 | I7: 0.65 | J7: 932 | K7: 6.8 | L7: 6 | M7: 2 | N7: 8 | O7: 2 | P7: =IFERROR((I7*0.35+K7*7+L7*6+J7/25-M7*10-(N7/F7)*50-(O7/G7)*40)/50,0) -> 1.9598383 | Q7: =100*(P7-MIN($P$2:$P$692))/(MAX($P$2:$P$692) - MIN($P$2:$P$692)) -> 1.3283951 | S7: 1.9598383 | T7: 4.98 | U7: 4.28 | V7: -0.53 | W7: 0.9 | X7: =IFERROR((U7*0.7+T7*0.15+S7*0.15*W12),0) -> 4.0075782 | Y7: =100*(X7-MIN($X$2:$X$692))/(MAX($X$2:$X$692) - MIN($X$2:$X$692)) -> 86.254347 | Z7: =Y7-Q7 -> 84.925952 | AB7: =IFERROR(__xludf.DUMMYFUNCTION("iferror(PERCENTRANK.INC(FILTER($X$2:$X$423, $U$2:$U$423<3.75), $X7), 1)"),0.997) -> 0.997 | AC7: =IFERROR(__xludf.DUMMYFUNCTION("iferror(PERCENTRANK.INC(FILTER($X$2:$X$423, $U$2:$U$423<4.25), $X7), 1)"),0.996) -> 0.996 | AD7: =IFERROR(__xludf.DUMMYFUNCTION("iferror(PERCENTRANK.INC(FILTER($X$2:$X$423, $U$2:$U$423>=4.1), $X7), 0.01)"),0.72) -> 0.72
A8: Colton Joseph | B8: DOMINION | C8: 1 | D8: QB | E8: Sun Belt | F8: 355 | G8: 311 | H8: 175 | I8: 0.563 | J8: 2649 | K8: 8.5 | L8: 21 | M8: 13 | N8: 18 | O8: 12 | P8: =IFERROR((I8*0.35+K8*7+L8*6+J8/25-M8*10-(N8/F8)*50-(O8/G8)*40)/50,0) -> 3.1515686 | Q8: =100*(P8-MIN($P$2:$P$692))/(MAX($P$2:$P$692) - MIN($P$2:$P$692)) -> 1.8935136 | S8: 3.1515686 | T8: 1.42 | U8: 4.78 | V8: -1.06 | W8: 0.95 | X8: =IFERROR((U8*0.7+T8*0.15+S8*0.15*W13),0) -> 3.9844618 | Y8: =100*(X8-MIN($X$2:$X$692))/(MAX($X$2:$X$692) - MIN($X$2:$X$692)) -> 85.968511 | Z8: =Y8-Q8 -> 84.074997 | AB8: =IFERROR(__xludf.DUMMYFUNCTION("iferror(PERCENTRANK.INC(FILTER($X$2:$X$423, $U$2:$U$423<3.75), $X8), 1)"),0.997) -> 0.997 | AC8: =IFERROR(__xludf.DUMMYFUNCTION("iferror(PERCENTRANK.INC(FILTER($X$2:$X$423, $U$2:$U$423<4.25), $X8), 1)"),0.996) -> 0.996 | AD8: =IFERROR(__xludf.DUMMYFUNCTION("iferror(PERCENTRANK.INC(FILTER($X$2:$X$423, $U$2:$U$423>=4.1), $X8), 0.01)"),0.68) -> 0.68
A9: Devon Dampier | B9: UTAH | C9: 4 | D9: QB | E9: Big 12 | F9: 356 | G9: 325 | H9: 196 | I9: 0.603 | J9: 2252 | K9: 6.9 | L9: 22 | M9: 6 | N9: 8 | O9: 10 | P9: =IFERROR((I9*0.35+K9*7+L9*6+J9/25-M9*10-(N9/F9)*50-(O9/G9)*40)/50,0) -> 4.1647337 | Q9: =100*(P9-MIN($P$2:$P$692))/(MAX($P$2:$P$692) - MIN($P$2:$P$692)) -> 2.3739565 | S9: 4.1647337 | T9: 1 | U9: 4.57 | V9: 0.09 | W9: 1 | X9: =IFERROR((U9*0.7+T9*0.15+S9*0.15*W14),0) -> 3.9424746 | Y9: =100*(X9-MIN($X$2:$X$692))/(MAX($X$2:$X$692) - MIN($X$2:$X$692)) -> 85.449336 | Z9: =Y9-Q9 -> 83.07538 | AB9: =IFERROR(__xludf.DUMMYFUNCTION("iferror(PERCENTRANK.INC(FILTER($X$2:$X$423, $U$2:$U$423<3.75), $X9), 1)"),0.997) -> 0.997 | AC9: =IFERROR(__xludf.DUMMYFUNCTION("iferror(PERCENTRANK.INC(FILTER($X$2:$X$423, $U$2:$U$423<4.25), $X9), 1)"),0.996) -> 0.996 | AD9: =IFERROR(__xludf.DUMMYFUNCTION("iferror(PERCENTRANK.INC(FILTER($X$2:$X$423, $U$2:$U$423>=4.1), $X9), 0.01)"),0.64) -> 0.64
A10: Trey Hedden | B10: FURMAN | C10: 8 | D10: QB | E10: Southern | F10: 464 | G10: 439 | H10: 291 | I10: 0.663 | J10: 2972 | K10: 6.8 | L10: 17 | M10: 13 | N10: 23 | O10: 14 | P10: =IFERROR((I10*0.35+K10*7+L10*6+J10/25-M10*10-(N10/F10)*50-(O10/G10)*40)/50,0) -> 2.6991595 | Q10: =100*(P10-MIN($P$2:$P$692))/(MAX($P$2:$P$692) - MIN($P$2:$P$692)) -> 1.6789812 | S10: 2.6991595 | T10: 2.64 | U10: 4.25 | V10: 13.19 | W10: 0.9 | X10: =IFERROR((U10*0.7+T10*0.15+S10*0.15*W15),0) -> 3.7758739 | Y10: =100*(X10-MIN($X$2:$X$692))/(MAX($X$2:$X$692) - MIN($X$2:$X$692)) -> 83.389309 | Z10: =Y10-Q10 -> 81.710328 | AB10: =IFERROR(__xludf.DUMMYFUNCTION("iferror(PERCENTRANK.INC(FILTER($X$2:$X$423, $U$2:$U$423<3.75), $X10), 1)"),0.996) -> 0.996 | AC10: =IFERROR(__xludf.DUMMYFUNCTION("iferror(PERCENTRANK.INC(FILTER($X$2:$X$423, $U$2:$U$423<4.25), $X10), 1)"),0.995) -> 0.995 | AD10: =IFERROR(__xludf.DUMMYFUNCTION("iferror(PERCENTRANK.INC(FILTER($X$2:$X$423, $U$2:$U$423>=4.1), $X10), 0.01)"),0.56) -> 0.56
A11: Collin Hurst | B11: PRESBYTERN | C11: 8 | D11: QB | E11: Pioneer | F11: 348 | G11: 317 | H11: 212 | I11: 0.669 | J11: 2786 | K11: 8.8 | L11: 26 | M11: 11 | N11: 16 | O11: 14 | P11: =IFERROR((I11*0.35+K11*7+L11*6+J11/25-M11*10-(N11/F11)*50-(O11/G11)*40)/50,0) -> 4.3041748 | Q11: =100*(P11-MIN($P$2:$P$692))/(MAX($P$2:$P$692) - MIN($P$2:$P$692)) -> 2.4400794 | S11: 4.3041748 | T11: 1.21 | U11: 4.24 | V11: 3.47 | W11: 0.9 | X11: =IFERROR((U11*0.7+T11*0.15+S11*0.15*W16),0) -> 3.7305636 | Y11: =100*(X11-MIN($X$2:$X$692))/(MAX($X$2:$X$692) - MIN($X$2:$X$692)) -> 82.829044 | Z11: =Y11-Q11 -> 80.388965 | AB11: =IFERROR(__xludf.DUMMYFUNCTION("iferror(PERCENTRANK.INC(FILTER($X$2:$X$423, $U$2:$U$423<3.75), $X11), 1)"),0.996) -> 0.996 | AC11: =IFERROR(__xludf.DUMMYFUNCTION("iferror(PERCENTRANK.INC(FILTER($X$2:$X$423, $U$2:$U$423<4.25), $X11), 1)"),0.993) -> 0.993 | AD11: =IFERROR(__xludf.DUMMYFUNCTION("iferror(PERCENTRANK.INC(FILTER($X$2:$X$423, $U$2:$U$423>=4.1), $X11), 0.01)"),0.44) -> 0.44
A12: Dean DeNobile | B12: LAFAYETTE | C12: 16 | D12: QB | E12: Patriot | F12: 388 | G12: 370 | H12: 230 | I12: 0.622 | J12: 2608 | K12: 7 | L12: 19 | M12: 7 | N12: 9 | O12: 8 | P12: =IFERROR((I12*0.35+K12*7+L12*6+J12/25-M12*10-(N12/F12)*50-(O12/G12)*40)/50,0) -> 3.9102608 | Q12: =100*(P12-MIN($P$2:$P$692))/(MAX($P$2:$P$692) - MIN($P$2:$P$692)) -> 2.2532854 | S12: 3.9102608 | T12: 0.99 | U12: 4.1 | V12: 1.29 | W12: 0.9 | X12: =IFERROR((U12*0.7+T12*0.15+S12*0.15*W17),0) -> 3.5463852 | Y12: =100*(X12-MIN($X$2:$X$692))/(MAX($X$2:$X$692) - MIN($X$2:$X$692)) -> 80.551667 | Z12: =Y12-Q12 -> 78.298381 | AB12: =IFERROR(__xludf.DUMMYFUNCTION("iferror(PERCENTRANK.INC(FILTER($X$2:$X$423, $U$2:$U$423<3.75), $X12), 1)"),0.995) -> 0.995 | AC12: =IFERROR(__xludf.DUMMYFUNCTION("iferror(PERCENTRANK.INC(FILTER($X$2:$X$423, $U$2:$U$423<4.25), $X12), 1)"),0.99) -> 0.99 | AD12: =IFERROR(__xludf.DUMMYFUNCTION("iferror(PERCENTRANK.INC(FILTER($X$2:$X$423, $U$2:$U$423>=4.1), $X12), 0.01)"),0.4) -> 0.4
A13: Coulter Cleland | B13: DAVIDSON | C13: 5 | D13: QB | E13: Pioneer | F13: 401 | G13: 334 | H13: 182 | I13: 0.545 | J13: 2140 | K13: 6.4 | L13: 20 | M13: 11 | N13: 25 | O13: 19 | P13: =IFERROR((I13*0.35+K13*7+L13*6+J13/25-M13*10-(N13/F13)*50-(O13/G13)*40)/50,0) -> 2.7039619 | Q13: =100*(P13-MIN($P$2:$P$692))/(MAX($P$2:$P$692) - MIN($P$2:$P$692)) -> 1.6812585 | S13: 2.7039619 | T13: 1.8 | U13: 4.02 | V13: -5.15 | W13: 0.9 | X13: =IFERROR((U13*0.7+T13*0.15+S13*0.15*W18),0) -> 3.4490349 | Y13: =100*(X13-MIN($X$2:$X$692))/(MAX($X$2:$X$692) - MIN($X$2:$X$692)) -> 79.347923 | Z13: =Y13-Q13 -> 77.666665 | AB13: =IFERROR(__xludf.DUMMYFUNCTION("iferror(PERCENTRANK.INC(FILTER($X$2:$X$423, $U$2:$U$423<3.75), $X13), 1)"),0.995) -> 0.995 | AC13: =IFERROR(__xludf.DUMMYFUNCTION("iferror(PERCENTRANK.INC(FILTER($X$2:$X$423, $U$2:$U$423<4.25), $X13), 1)"),0.988) -> 0.988 | AD13: =IFERROR(__xludf.DUMMYFUNCTION("iferror(PERCENTRANK.INC(FILTER($X$2:$X$423, $U$2:$U$423>=4.1), $X13), 0.01)"),0.347) -> 0.347
A14: Jackson Brousseau | B14: COLO STATE | C14: 7 | D14: QB | E14: MWC | F14: 265 | G14: 215 | H14: 134 | I14: 0.623 | J14: 1400 | K14: 6.5 | L14: 9 | M14: 3 | N14: 22 | O14: 9 | P14: =IFERROR((I14*0.35+K14*7+L14*6+J14/25-M14*10-(N14/F14)*50-(O14/G14)*40)/50,0) -> 2.3978538 | Q14: =100*(P14-MIN($P$2:$P$692))/(MAX($P$2:$P$692) - MIN($P$2:$P$692)) -> 1.5361021 | S14: 2.3978538 | T14: 0.13 | U14: 4.3 | V14: 3.82 | W14: 0.95 | X14: =IFERROR((U14*0.7+T14*0.15+S14*0.15*W19),0) -> 3.3711942 | Y14: =100*(X14-MIN($X$2:$X$692))/(MAX($X$2:$X$692) - MIN($X$2:$X$692)) -> 78.385418 | Z14: =Y14-Q14 -> 76.849316 | AB14: =IFERROR(__xludf.DUMMYFUNCTION("iferror(PERCENTRANK.INC(FILTER($X$2:$X$423, $U$2:$U$423<3.75), $X14), 1)"),0.995) -> 0.995 | AC14: =IFERROR(__xludf.DUMMYFUNCTION("iferror(PERCENTRANK.INC(FILTER($X$2:$X$423, $U$2:$U$423<4.25), $X14), 1)"),0.986) -> 0.986 | AD14: =IFERROR(__xludf.DUMMYFUNCTION("iferror(PERCENTRANK.INC(FILTER($X$2:$X$423, $U$2:$U$423>=4.1), $X14), 0.01)"),0.32) -> 0.32
A15: Eli Holstein | B15: PITTSBURGH | C15: 10 | D15: QB | E15: ACC | F15: 153 | G15: 132 | H15: 78 | I15: 0.591 | J15: 1084 | K15: 8.2 | L15: 12 | M15: 6 | N15: 9 | O15: 11 | P15: =IFERROR((I15*0.35+K15*7+L15*6+J15/25-M15*10-(N15/F15)*50-(O15/G15)*40)/50,0) -> 2.1338468 | Q15: =100*(P15-MIN($P$2:$P$692))/(MAX($P$2:$P$692) - MIN($P$2:$P$692)) -> 1.41091 | S15: 2.1338468 | T15: 0.46 | U15: 4.28 | V15: -0.53 | W15: 1 | X15: =IFERROR((U15*0.7+T15*0.15+S15*0.15*W20),0) -> 3.3690732 | Y15: =100*(X15-MIN($X$2:$X$692))/(MAX($X$2:$X$692) - MIN($X$2:$X$692)) -> 78.359192 | Z15: =Y15-Q15 -> 76.948282 | AB15: =IFERROR(__xludf.DUMMYFUNCTION("iferror(PERCENTRANK.INC(FILTER($X$2:$X$423, $U$2:$U$423<3.75), $X15), 1)"),0.995) -> 0.995 | AC15: =IFERROR(__xludf.DUMMYFUNCTION("iferror(PERCENTRANK.INC(FILTER($X$2:$X$423, $U$2:$U$423<4.25), $X15), 1)"),0.986) -> 0.986 | AD15: =IFERROR(__xludf.DUMMYFUNCTION("iferror(PERCENTRANK.INC(FILTER($X$2:$X$423, $U$2:$U$423>=4.1), $X15), 0.01)"),0.28) -> 0.28
A16: Jared Lockhart | B16: JACKSON ST | C16: 11 | D16: QB | E16: SWAC | F16: 141 | G16: 111 | H16: 72 | I16: 0.649 | J16: 1128 | K16: 10.2 | L16: 7 | M16: 2 | N16: 8 | O16: 5 | P16: =IFERROR((I16*0.35+K16*7+L16*6+J16/25-M16*10-(N16/F16)*50-(O16/G16)*40)/50,0) -> 2.6821694 | Q16: =100*(P16-MIN($P$2:$P$692))/(MAX($P$2:$P$692) - MIN($P$2:$P$692)) -> 1.6709245 | S16: 2.6821694 | T16: 2.63 | U16: 3.68 | V16: -5.05 | W16: 0.9 | X16: =IFERROR((U16*0.7+T16*0.15+S16*0.15*W21),0) -> 3.3325929 | Y16: =100*(X16-MIN($X$2:$X$692))/(MAX($X$2:$X$692) - MIN($X$2:$X$692)) -> 77.908111 | Z16: =Y16-Q16 -> 76.237186 | AB16: =IFERROR(__xludf.DUMMYFUNCTION("iferror(PERCENTRANK.INC(FILTER($X$2:$X$423, $U$2:$U$423<3.75), $X16), 1)"),0.995) -> 0.995 | AC16: =IFERROR(__xludf.DUMMYFUNCTION("iferror(PERCENTRANK.INC(FILTER($X$2:$X$423, $U$2:$U$423<4.25), $X16), 1)"),0.983) -> 0.983 | AD16: =IFERROR(__xludf.DUMMYFUNCTION("iferror(PERCENTRANK.INC(FILTER($X$2:$X$423, $U$2:$U$423>=4.1), $X16), 0.01)"),0.237) -> 0.237
A17: Liam O'Brien | B17: PENN | C17: 2 | D17: QB | E17: Ivy | F17: 380 | G17: 338 | H17: 219 | I17: 0.648 | J17: 2499 | K17: 7.4 | L17: 19 | M17: 7 | N17: 19 | O17: 14 | P17: =IFERROR((I17*0.35+K17*7+L17*6+J17/25-M17*10-(N17/F17)*50-(O17/G17)*40)/50,0) -> 3.8365999 | Q17: =100*(P17-MIN($P$2:$P$692))/(MAX($P$2:$P$692) - MIN($P$2:$P$692)) -> 2.2183554 | S17: 3.8365999 | T17: 1.32 | U17: 3.69 | V17: 5.45 | W17: 0.9 | X17: =IFERROR((U17*0.7+T17*0.15+S17*0.15*W22),0) -> 3.298941 | Y17: =100*(X17-MIN($X$2:$X$692))/(MAX($X$2:$X$692) - MIN($X$2:$X$692)) -> 77.492003 | Z17: =Y17-Q17 -> 75.273648 | AB17: =IFERROR(__xludf.DUMMYFUNCTION("iferror(PERCENTRANK.INC(FILTER($X$2:$X$423, $U$2:$U$423<3.75), $X17), 1)"),0.992) -> 0.992 | AC17: =IFERROR(__xludf.DUMMYFUNCTION("iferror(PERCENTRANK.INC(FILTER($X$2:$X$423, $U$2:$U$423<4.25), $X17), 1)"),0.98) -> 0.98 | AD17: =IFERROR(__xludf.DUMMYFUNCTION("iferror(PERCENTRANK.INC(FILTER($X$2:$X$423, $U$2:$U$423>=4.1), $X17), 0.01)"),0.229) -> 0.229
A18: Johnny Weber | B18: SE MO ST | C18: 4 | D18: QB | E18: Big South - OVC Football Association | F18: 217 | G18: 194 | H18: 114 | I18: 0.588 | J18: 1178 | K18: 6.1 | L18: 8 | M18: 5 | N18: 14 | O18: 9 | P18: =IFERROR((I18*0.35+K18*7+L18*6+J18/25-M18*10-(N18/F18)*50-(O18/G18)*40)/50,0) -> 1.6588865 | Q18: =100*(P18-MIN($P$2:$P$692))/(MAX($P$2:$P$692) - MIN($P$2:$P$692)) -> 1.1856838 | S18: 1.6588865 | T18: 4.2 | U18: 3.43 | V18: 8.05 | W18: 0.9 | X18: =IFERROR((U18*0.7+T18*0.15+S18*0.15*W23),0) -> 3.2673913 | Y18: =100*(X18-MIN($X$2:$X$692))/(MAX($X$2:$X$692) - MIN($X$2:$X$692)) -> 77.10189 | Z18: =Y18-Q18 -> 75.916206 | AB18: =IFERROR(__xludf.DUMMYFUNCTION("iferror(PERCENTRANK.INC(FILTER($X$2:$X$423, $U$2:$U$423<3.75), $X18), 1)"),0.99) -> 0.99 | AC18: =IFERROR(__xludf.DUMMYFUNCTION("iferror(PERCENTRANK.INC(FILTER($X$2:$X$423, $U$2:$U$423<4.25), $X18), 1)"),0.975) -> 0.975 | AD18: =IFERROR(__xludf.DUMMYFUNCTION("iferror(PERCENTRANK.INC(FILTER($X$2:$X$423, $U$2:$U$423>=4.1), $X18), 0.01)"),0.222) -> 0.222
A19: Amari Odom | B19: KENNESAW | C19: 2 | D19: QB | E19: C-USA | F19: 285 | G19: 241 | H19: 152 | I19: 0.631 | J19: 2335 | K19: 9.7 | L19: 17 | M19: 7 | N19: 13 | O19: 11 | P19: =IFERROR((I19*0.35+K19*7+L19*6+J19/25-M19*10-(N19/F19)*50-(O19/G19)*40)/50,0) -> 3.7882884 | Q19: =100*(P19-MIN($P$2:$P$692))/(MAX($P$2:$P$692) - MIN($P$2:$P$692)) -> 2.1954461 | S19: 3.7882884 | T19: 0.55 | U19: 3.82 | V19: -6.42 | W19: 0.95 | X19: =IFERROR((U19*0.7+T19*0.15+S19*0.15*W24),0) -> 3.2679189 | Y19: =100*(X19-MIN($X$2:$X$692))/(MAX($X$2:$X$692) - MIN($X$2:$X$692)) -> 77.108414 | Z19: =Y19-Q19 -> 74.912967 | AB19: =IFERROR(__xludf.DUMMYFUNCTION("iferror(PERCENTRANK.INC(FILTER($X$2:$X$423, $U$2:$U$423<3.75), $X19), 1)"),0.99) -> 0.99 | AC19: =IFERROR(__xludf.DUMMYFUNCTION("iferror(PERCENTRANK.INC(FILTER($X$2:$X$423, $U$2:$U$423<4.25), $X19), 1)"),0.978) -> 0.978 | AD19: =IFERROR(__xludf.DUMMYFUNCTION("iferror(PERCENTRANK.INC(FILTER($X$2:$X$423, $U$2:$U$423>=4.1), $X19), 0.01)"),0.222) -> 0.222
A20: Grant Jordan | B20: UMASS | C20: 9 | D20: QB | E20: MAC | F20: 130 | G20: 110 | H20: 62 | I20: 0.564 | J20: 580 | K20: 5.3 | L20: 3 | M20: 3 | N20: 12 | O20: 3 | P20: =IFERROR((I20*0.35+K20*7+L20*6+J20/25-M20*10-(N20/F20)*50-(O20/G20)*40)/50,0) -> 0.85582213 | Q20: =100*(P20-MIN($P$2:$P$692))/(MAX($P$2:$P$692) - MIN($P$2:$P$692)) -> 0.80487071 | S20: 0.85582213 | T20: -0.67 | U20: 4.5 | V20: -2.81 | W20: 0.95 | X20: =IFERROR((U20*0.7+T20*0.15+S20*0.15*W25),0) -> 3.1714547 | Y20: =100*(X20-MIN($X$2:$X$692))/(MAX($X$2:$X$692) - MIN($X$2:$X$692)) -> 75.915627 | Z20: =Y20-Q20 -> 75.110756 | AB20: =IFERROR(__xludf.DUMMYFUNCTION("iferror(PERCENTRANK.INC(FILTER($X$2:$X$423, $U$2:$U$423<3.75), $X20), 1)"),0.988) -> 0.988 | AC20: =IFERROR(__xludf.DUMMYFUNCTION("iferror(PERCENTRANK.INC(FILTER($X$2:$X$423, $U$2:$U$423<4.25), $X20), 1)"),0.973) -> 0.973 | AD20: =IFERROR(__xludf.DUMMYFUNCTION("iferror(PERCENTRANK.INC(FILTER($X$2:$X$423, $U$2:$U$423>=4.1), $X20), 0.01)"),0.2) -> 0.2
A21: Carson Camp | B21: SE LA | C21: 18 | D21: QB | E21: Southland | F21: 272 | G21: 233 | H21: 142 | I21: 0.609 | J21: 1780 | K21: 7.6 | L21: 14 | M21: 8 | N21: 16 | O21: 8 | P21: =IFERROR((I21*0.35+K21*7+L21*6+J21/25-M21*10-(N21/F21)*50-(O21/G21)*40)/50,0) -> 2.4859717 | Q21: =100*(P21-MIN($P$2:$P$692))/(MAX($P$2:$P$692) - MIN($P$2:$P$692)) -> 1.5778876 | S21: 2.4859717 | T21: 1.55 | U21: 3.63 | V21: -5.91 | W21: 0.9 | X21: =IFERROR((U21*0.7+T21*0.15+S21*0.15*W26),0) -> 3.127751 | Y21: =100*(X21-MIN($X$2:$X$692))/(MAX($X$2:$X$692) - MIN($X$2:$X$692)) -> 75.375228 | Z21: =Y21-Q21 -> 73.79734 | AB21: =IFERROR(__xludf.DUMMYFUNCTION("iferror(PERCENTRANK.INC(FILTER($X$2:$X$423, $U$2:$U$423<3.75), $X21), 1)"),0.987) -> 0.987 | AC21: =IFERROR(__xludf.DUMMYFUNCTION("iferror(PERCENTRANK.INC(FILTER($X$2:$X$423, $U$2:$U$423<4.25), $X21), 1)"),0.973) -> 0.973 | AD21: =IFERROR(__xludf.DUMMYFUNCTION("iferror(PERCENTRANK.INC(FILTER($X$2:$X$423, $U$2:$U$423>=4.1), $X21), 0.01)"),0.19) -> 0.19
A22: Sonny Mannino | B22: MARIST | C22: 12 | D22: QB | E22: Pioneer | F22: 384 | G22: 289 | H22: 163 | I22: 0.564 | J22: 1818 | K22: 6.3 | L22: 11 | M22: 4 | N22: 30 | O22: 11 | P22: =IFERROR((I22*0.35+K22*7+L22*6+J22/25-M22*10-(N22/F22)*50-(O22/G22)*40)/50,0) -> 2.7517732 | Q22: =100*(P22-MIN($P$2:$P$692))/(MAX($P$2:$P$692) - MIN($P$2:$P$692)) -> 1.7039306 | S22: 2.7517732 | T22: -1 | U22: 4.06 | V22: 3.99 | W22: 0.9 | X22: =IFERROR((U22*0.7+T22*0.15+S22*0.15*W27),0) -> 3.0634894 | Y22: =100*(X22-MIN($X$2:$X$692))/(MAX($X$2:$X$692) - MIN($X$2:$X$692)) -> 74.580629 | Z22: =Y22-Q22 -> 72.876699 | AB22: =IFERROR(__xludf.DUMMYFUNCTION("iferror(PERCENTRANK.INC(FILTER($X$2:$X$423, $U$2:$U$423<3.75), $X22), 1)"),0.987) -> 0.987 | AC22: =IFERROR(__xludf.DUMMYFUNCTION("iferror(PERCENTRANK.INC(FILTER($X$2:$X$423, $U$2:$U$423<4.25), $X22), 1)"),0.97) -> 0.97 | AD22: =IFERROR(__xludf.DUMMYFUNCTION("iferror(PERCENTRANK.INC(FILTER($X$2:$X$423, $U$2:$U$423>=4.1), $X22), 0.01)"),0.174) -> 0.174
A23: AJ Hairston | B23: UMASS | C23: 8 | D23: QB | E23: MAC | F23: 269 | G23: 232 | H23: 111 | I23: 0.478 | J23: 1022 | K23: 4.4 | L23: 4 | M23: 4 | N23: 17 | O23: 6 | P23: =IFERROR((I23*0.35+K23*7+L23*6+J23/25-M23*10-(N23/F23)*50-(O23/G23)*40)/50,0) -> 1.0330593 | Q23: =100*(P23-MIN($P$2:$P$692))/(MAX($P$2:$P$692) - MIN($P$2:$P$692)) -> 0.88891658 | S23: 1.0330593 | T23: -0.74 | U23: 4.24 | V23: 8.95 | W23: 0.95 | X23: =IFERROR((U23*0.7+T23*0.15+S23*0.15*W28),0) -> 3.004211 | Y23: =100*(X23-MIN($X$2:$X$692))/(MAX($X$2:$X$692) - MIN($X$2:$X$692)) -> 73.847648 | Z23: =Y23-Q23 -> 72.958731 | AB23: =IFERROR(__xludf.DUMMYFUNCTION("iferror(PERCENTRANK.INC(FILTER($X$2:$X$423, $U$2:$U$423<3.75), $X23), 1)"),0.987) -> 0.987 | AC23: =IFERROR(__xludf.DUMMYFUNCTION("iferror(PERCENTRANK.INC(FILTER($X$2:$X$423, $U$2:$U$423<4.25), $X23), 1)"),0.968) -> 0.968 | AD23: =IFERROR(__xludf.DUMMYFUNCTION("iferror(PERCENTRANK.INC(FILTER($X$2:$X$423, $U$2:$U$423>=4.1), $X23), 0.01)"),0.16) -> 0.16
A24: Davin Wydner | B24: W GEORGIA | C24: 2 | D24: QB | E24: United Athletic | F24: 341 | G24: 284 | H24: 153 | I24: 0.539 | J24: 1714 | K24: 6 | L24: 15 | M24: 9 | N24: 20 | O24: 13 | P24: =IFERROR((I24*0.35+K24*7+L24*6+J24/25-M24*10-(N24/F24)*50-(O24/G24)*40)/50,0) -> 2.1197023 | Q24: =100*(P24-MIN($P$2:$P$692))/(MAX($P$2:$P$692) - MIN($P$2:$P$692)) -> 1.4042026 | S24: 2.1197023 | T24: -0.81 | U24: 3.8 | V24: -0.63 | W24: 0.9 | X24: =IFERROR((U24*0.7+T24*0.15+S24*0.15*W29),0) -> 2.8564553 | Y24: =100*(X24-MIN($X$2:$X$692))/(MAX($X$2:$X$692) - MIN($X$2:$X$692)) -> 72.02064 | Z24: =Y24-Q24 -> 70.616438 | AB24: =IFERROR(__xludf.DUMMYFUNCTION("iferror(PERCENTRANK.INC(FILTER($X$2:$X$423, $U$2:$U$423<3.75), $X24), 1)"),0.986) -> 0.986 | AC24: =IFERROR(__xludf.DUMMYFUNCTION("iferror(PERCENTRANK.INC(FILTER($X$2:$X$423, $U$2:$U$423<4.25), $X24), 1)"),0.965) -> 0.965 | AD24: =IFERROR(__xludf.DUMMYFUNCTION("iferror(PERCENTRANK.INC(FILTER($X$2:$X$423, $U$2:$U$423>=4.1), $X24), 0.01)"),0.117) -> 0.117
A25: Brandon Tennison | B25: UTSA | C25: 17 | D25: QB | E25: The American | F25: 39 | G25: 33 | H25: 20 | I25: 0.606 | J25: 199 | K25: 6 | L25: 2 | M25: 0 | N25: 2 | O25: 0 | P25: =IFERROR((I25*0.35+K25*7+L25*6+J25/25-M25*10-(N25/F25)*50-(O25/G25)*40)/50,0) -> 1.1921599 | Q25: =100*(P25-MIN($P$2:$P$692))/(MAX($P$2:$P$692) - MIN($P$2:$P$692)) -> 0.9643621 | S25: 1.1921599 | T25: 10 | U25: 3.7 | V25: -4.2 | W25: 0.95 | X25: =IFERROR((U25*0.7+T25*0.15+S25*0.15*W30),0) -> 4.268824 | Y25: =100*(X25-MIN($X$2:$X$692))/(MAX($X$2:$X$692) - MIN($X$2:$X$692)) -> 89.484668 | Z25: =Y25-Q25 -> 88.520306 | AB25: =IFERROR(__xludf.DUMMYFUNCTION("iferror(PERCENTRANK.INC(FILTER($X$2:$X$423, $U$2:$U$423<3.75), $X25), 1)"),0.997) -> 0.997 | AC25: =IFERROR(__xludf.DUMMYFUNCTION("iferror(PERCENTRANK.INC(FILTER($X$2:$X$423, $U$2:$U$423<4.25), $X25), 1)"),0.998) -> 0.998 | AD25: =IFERROR(__xludf.DUMMYFUNCTION("iferror(PERCENTRANK.INC(FILTER($X$2:$X$423, $U$2:$U$423>=4.1), $X25), 0.01)"),0.787) -> 0.787
A26: Brayden Fowler-Nicolosi | B26: COLO STATE | C26: 16 | D26: QB | E26: MWC | F26: 99 | G26: 86 | H26: 45 | I26: 0.523 | J26: 495 | K26: 5.8 | L26: 1 | M26: 2 | N26: 6 | O26: 4 | P26: =IFERROR((I26*0.35+K26*7+L26*6+J26/25-M26*10-(N26/F26)*50-(O26/G26)*40)/50,0) -> 0.83384564 | Q26: =100*(P26-MIN($P$2:$P$692))/(MAX($P$2:$P$692) - MIN($P$2:$P$692)) -> 0.79444946 | S26: 0.83384564 | T26: -2.49 | U26: 3.58 | V26: 5.19 | W26: 0.95 | X26: =IFERROR((U26*0.7+T26*0.15+S26*0.15*W31),0) -> 2.2450692 | Y26: =100*(X26-MIN($X$2:$X$692))/(MAX($X$2:$X$692) - MIN($X$2:$X$692)) -> 64.460812 | Z26: =Y26-Q26 -> 63.666362 | AB26: =IFERROR(__xludf.DUMMYFUNCTION("iferror(PERCENTRANK.INC(FILTER($X$2:$X$423, $U$2:$U$423<3.75), $X26), 1)"),0.982) -> 0.982 | AC26: =IFERROR(__xludf.DUMMYFUNCTION("iferror(PERCENTRANK.INC(FILTER($X$2:$X$423, $U$2:$U$423<4.25), $X26), 1)"),0.953) -> 0.953 | AD26: =IFERROR(__xludf.DUMMYFUNCTION("iferror(PERCENTRANK.INC(FILTER($X$2:$X$423, $U$2:$U$423>=4.1), $X26), 0.01)"),0.075) -> 0.075
A27: Taron Dickens | B27: W CAROLINA | C27: 5 | D27: QB | E27: Southern | F27: 459 | G27: 387 | H27: 276 | I27: 0.713 | J27: 3603 | K27: 9.3 | L27: 38 | M27: 4 | N27: 22 | O27: 8 | P27: =IFERROR((I27*0.35+K27*7+L27*6+J27/25-M27*10-(N27/F27)*50-(O27/G27)*40)/50,0) -> 7.8849232 | Q27: =100*(P27-MIN($P$2:$P$692))/(MAX($P$2:$P$692) - MIN($P$2:$P$692)) -> 4.1380702 | S27: 7.8849232 | T27: 2.69 | W27: 0.9 | X27: =IFERROR((U27*0.7+T27*0.15+S27*0.15*W32),0) -> 1.4679646 | Y27: =100*(X27-MIN($X$2:$X$692))/(MAX($X$2:$X$692) - MIN($X$2:$X$692)) -> 54.851865 | Z27: =Y27-Q27 -> 50.713795 | AB27: =IFERROR(__xludf.DUMMYFUNCTION("iferror(PERCENTRANK.INC(FILTER($X$2:$X$423, $U$2:$U$423<3.75), $X27), 1)"),0.969) -> 0.969 | AC27: =IFERROR(__xludf.DUMMYFUNCTION("iferror(PERCENTRANK.INC(FILTER($X$2:$X$423, $U$2:$U$423<4.25), $X27), 1)"),0.94) -> 0.94 | AD27: =IFERROR(__xludf.DUMMYFUNCTION("iferror(PERCENTRANK.INC(FILTER($X$2:$X$423, $U$2:$U$423>=4.1), $X27), 0.01)"),0.063) -> 0.063
A28: Drew Mestemaker | B28: N TEXAS | C28: 17 | D28: QB | E28: The American | F28: 437 | G28: 407 | H28: 278 | I28: 0.683 | J28: 3873 | K28: 9.5 | L28: 29 | M28: 6 | N28: 15 | O28: 11 | P28: =IFERROR((I28*0.35+K28*7+L28*6+J28/25-M28*10-(N28/F28)*50-(O28/G28)*40)/50,0) -> 6.6572344 | Q28: =100*(P28-MIN($P$2:$P$692))/(MAX($P$2:$P$692) - MIN($P$2:$P$692)) -> 3.5559002 | S28: 6.6572344 | T28: 1.01 | U28: 5.24 | V28: 19.55 | W28: 0.95 | X28: =IFERROR((U28*0.7+T28*0.15+S28*0.15*W33),0) -> 4.8180852 | Y28: =100*(X28-MIN($X$2:$X$692))/(MAX($X$2:$X$692) - MIN($X$2:$X$692)) -> 96.276317 | Z28: =Y28-Q28 -> 92.720417 | AB28: =IFERROR(__xludf.DUMMYFUNCTION("iferror(PERCENTRANK.INC(FILTER($X$2:$X$423, $U$2:$U$423<3.75), $X28), 1)"),1.0) -> 1 | AC28: =IFERROR(__xludf.DUMMYFUNCTION("iferror(PERCENTRANK.INC(FILTER($X$2:$X$423, $U$2:$U$423<4.25), $X28), 1)"),1.0) -> 1 | AD28: =IFERROR(__xludf.DUMMYFUNCTION("iferror(PERCENTRANK.INC(FILTER($X$2:$X$423, $U$2:$U$423>=4.1), $X28), 0.01)"),0.96) -> 0.96
A29: Darian Mensah | B29: DUKE | C29: 10 | D29: QB | E29: ACC | F29: 501 | G29: 456 | H29: 295 | I29: 0.647 | J29: 3475 | K29: 7.6 | L29: 28 | M29: 4 | N29: 26 | O29: 15 | P29: =IFERROR((I29*0.35+K29*7+L29*6+J29/25-M29*10-(N29/F29)*50-(O29/G29)*40)/50,0) -> 6.330317 | Q29: =100*(P29-MIN($P$2:$P$692))/(MAX($P$2:$P$692) - MIN($P$2:$P$692)) -> 3.400876 | S29: 6.330317 | T29: 1.04 | W29: 1 | X29: =IFERROR((U29*0.7+T29*0.15+S29*0.15*W34),0) -> 1.0105928 | Y29: =100*(X29-MIN($X$2:$X$692))/(MAX($X$2:$X$692) - MIN($X$2:$X$692)) -> 49.196433 | Z29: =Y29-Q29 -> 45.795557 | AB29: =IFERROR(__xludf.DUMMYFUNCTION("iferror(PERCENTRANK.INC(FILTER($X$2:$X$423, $U$2:$U$423<3.75), $X29), 1)"),0.938) -> 0.938 | AC29: =IFERROR(__xludf.DUMMYFUNCTION("iferror(PERCENTRANK.INC(FILTER($X$2:$X$423, $U$2:$U$423<4.25), $X29), 1)"),0.91) -> 0.91 | AD29: =IFERROR(__xludf.DUMMYFUNCTION("iferror(PERCENTRANK.INC(FILTER($X$2:$X$423, $U$2:$U$423>=4.1), $X29), 0.01)"),0.056) -> 0.056
A30: Fernando Mendoza | B30: INDIANA | C30: 15 | D30: QB | E30: Big Ten | F30: 358 | G30: 316 | H30: 216 | I30: 0.683 | J30: 2804 | K30: 8.9 | L30: 32 | M30: 5 | N30: 17 | O30: 9 | P30: =IFERROR((I30*0.35+K30*7+L30*6+J30/25-M30*10-(N30/F30)*50-(O30/G30)*40)/50,0) -> 6.2637102 | Q30: =100*(P30-MIN($P$2:$P$692))/(MAX($P$2:$P$692) - MIN($P$2:$P$692)) -> 3.369291 | S30: 6.2637102 | T30: 1.31 | W30: 1 | X30: =IFERROR((U30*0.7+T30*0.15+S30*0.15*W35),0) -> 1.0421009 | Y30: =100*(X30-MIN($X$2:$X$692))/(MAX($X$2:$X$692) - MIN($X$2:$X$692)) -> 49.586033 | Z30: =Y30-Q30 -> 46.216742 | AB30: =IFERROR(__xludf.DUMMYFUNCTION("iferror(PERCENTRANK.INC(FILTER($X$2:$X$423, $U$2:$U$423<3.75), $X30), 1)"),0.943) -> 0.943 | AC30: =IFERROR(__xludf.DUMMYFUNCTION("iferror(PERCENTRANK.INC(FILTER($X$2:$X$423, $U$2:$U$423<4.25), $X30), 1)"),0.915) -> 0.915 | AD30: =IFERROR(__xludf.DUMMYFUNCTION("iferror(PERCENTRANK.INC(FILTER($X$2:$X$423, $U$2:$U$423>=4.1), $X30), 0.01)"),0.056) -> 0.056
A31: Braden Atkinson | B31: MERCER | C31: 11 | D31: QB | E31: Southern | F31: 394 | G31: 389 | H31: 256 | I31: 0.658 | J31: 3494 | K31: 9 | L31: 34 | M31: 8 | N31: 2 | O31: 10 | P31: =IFERROR((I31*0.35+K31*7+L31*6+J31/25-M31*10-(N31/F31)*50-(O31/G31)*40)/50,0) -> 6.5141643 | Q31: =100*(P31-MIN($P$2:$P$692))/(MAX($P$2:$P$692) - MIN($P$2:$P$692)) -> 3.4880564 | S31: 6.5141643 | T31: 1.48 | W31: 0.9 | X31: =IFERROR((U31*0.7+T31*0.15+S31*0.15*W36),0) -> 1.1991246 | Y31: =100*(X31-MIN($X$2:$X$692))/(MAX($X$2:$X$692) - MIN($X$2:$X$692)) -> 51.527642 | Z31: =Y31-Q31 -> 48.039585 | AB31: =IFERROR(__xludf.DUMMYFUNCTION("iferror(PERCENTRANK.INC(FILTER($X$2:$X$423, $U$2:$U$423<3.75), $X31), 1)"),0.951) -> 0.951 | AC31: =IFERROR(__xludf.DUMMYFUNCTION("iferror(PERCENTRANK.INC(FILTER($X$2:$X$423, $U$2:$U$423<4.25), $X31), 1)"),0.923) -> 0.923 | AD31: =IFERROR(__xludf.DUMMYFUNCTION("iferror(PERCENTRANK.INC(FILTER($X$2:$X$423, $U$2:$U$423>=4.1), $X31), 0.01)"),0.059) -> 0.059
A32: Beau Brungard | B32: YNGTOWN ST | C32: 12 | D32: QB | E32: Missouri Valley | F32: 517 | G32: 429 | H32: 287 | I32: 0.669 | J32: 3319 | K32: 7.7 | L32: 26 | M32: 4 | N32: 16 | O32: 10 | P32: =IFERROR((I32*0.35+K32*7+L32*6+J32/25-M32*10-(N32/F32)*50-(O32/G32)*40)/50,0) -> 6.0082872 | Q32: =100*(P32-MIN($P$2:$P$692))/(MAX($P$2:$P$692) - MIN($P$2:$P$692)) -> 3.2481695 | S32: 6.0082872 | T32: 0.85 | W32: 0.9 | X32: =IFERROR((U32*0.7+T32*0.15+S32*0.15*W37),0) -> 0.98368093 | Y32: =100*(X32-MIN($X$2:$X$692))/(MAX($X$2:$X$692) - MIN($X$2:$X$692)) -> 48.863666 | Z32: =Y32-Q32 -> 45.615497 | AB32: =IFERROR(__xludf.DUMMYFUNCTION("iferror(PERCENTRANK.INC(FILTER($X$2:$X$423, $U$2:$U$423<3.75), $X32), 1)"),0.936) -> 0.936 | AC32: =IFERROR(__xludf.DUMMYFUNCTION("iferror(PERCENTRANK.INC(FILTER($X$2:$X$423, $U$2:$U$423<4.25), $X32), 1)"),0.908) -> 0.908 | AD32: =IFERROR(__xludf.DUMMYFUNCTION("iferror(PERCENTRANK.INC(FILTER($X$2:$X$423, $U$2:$U$423>=4.1), $X32), 0.01)"),0.055) -> 0.055
A33: Julian Sayin | B33: OHIO STATE | C33: 10 | D33: QB | E33: Big Ten | F33: 363 | G33: 339 | H33: 261 | I33: 0.77 | J33: 3087 | K33: 9.1 | L33: 30 | M33: 5 | N33: 9 | O33: 5 | P33: =IFERROR((I33*0.35+K33*7+L33*6+J33/25-M33*10-(N33/F33)*50-(O33/G33)*40)/50,0) -> 6.3123972 | Q33: =100*(P33-MIN($P$2:$P$692))/(MAX($P$2:$P$692) - MIN($P$2:$P$692)) -> 3.3923784 | S33: 6.3123972 | T33: 1.01 | W33: 1 | X33: =IFERROR((U33*0.7+T33*0.15+S33*0.15*W38),0) -> 1.0983596 | Y33: =100*(X33-MIN($X$2:$X$692))/(MAX($X$2:$X$692) - MIN($X$2:$X$692)) -> 50.281675 | Z33: =Y33-Q33 -> 46.889297 | AB33: =IFERROR(__xludf.DUMMYFUNCTION("iferror(PERCENTRANK.INC(FILTER($X$2:$X$423, $U$2:$U$423<3.75), $X33), 1)"),0.946) -> 0.946 | AC33: =IFERROR(__xludf.DUMMYFUNCTION("iferror(PERCENTRANK.INC(FILTER($X$2:$X$423, $U$2:$U$423<4.25), $X33), 1)"),0.918) -> 0.918 | AD33: =IFERROR(__xludf.DUMMYFUNCTION("iferror(PERCENTRANK.INC(FILTER($X$2:$X$423, $U$2:$U$423>=4.1), $X33), 0.01)"),0.057) -> 0.057
A34: Eddie Lee Marburger | B34: TXGV | C34: 12 | D34: QB | E34: Southland | F34: 368 | G34: 318 | H34: 203 | I34: 0.638 | J34: 2856 | K34: 9 | L34: 31 | M34: 8 | N34: 22 | O34: 10 | P34: =IFERROR((I34*0.35+K34*7+L34*6+J34/25-M34*10-(N34/F34)*50-(O34/G34)*40)/50,0) -> 5.5843262 | Q34: =100*(P34-MIN($P$2:$P$692))/(MAX($P$2:$P$692) - MIN($P$2:$P$692)) -> 3.0471271 | S34: 5.5843262 | T34: 4.24 | W34: 0.9 | X34: =IFERROR((U34*0.7+T34*0.15+S34*0.15*W39),0) -> 1.389884 | Y34: =100*(X34-MIN($X$2:$X$692))/(MAX($X$2:$X$692) - MIN($X$2:$X$692)) -> 53.886393 | Z34: =Y34-Q34 -> 50.839266 | AB34: =IFERROR(__xludf.DUMMYFUNCTION("iferror(PERCENTRANK.INC(FILTER($X$2:$X$423, $U$2:$U$423<3.75), $X34), 1)"),0.966) -> 0.966 | AC34: =IFERROR(__xludf.DUMMYFUNCTION("iferror(PERCENTRANK.INC(FILTER($X$2:$X$423, $U$2:$U$423<4.25), $X34), 1)"),0.938) -> 0.938 | AD34: =IFERROR(__xludf.DUMMYFUNCTION("iferror(PERCENTRANK.INC(FILTER($X$2:$X$423, $U$2:$U$423>=4.1), $X34), 0.01)"),0.062) -> 0.062
A35: Derek Robertson | B35: MONMOUTH | C35: 12 | D35: QB | E35: CAA | F35: 294 | G35: 279 | H35: 196 | I35: 0.703 | J35: 2585 | K35: 9.3 | L35: 27 | M35: 5 | N35: 9 | O35: 8 | P35: =IFERROR((I35*0.35+K35*7+L35*6+J35/25-M35*10-(N35/F35)*50-(O35/G35)*40)/50,0) -> 5.5613697 | Q35: =100*(P35-MIN($P$2:$P$692))/(MAX($P$2:$P$692) - MIN($P$2:$P$692)) -> 3.0362412 | S35: 5.5613697 | T35: 1.46 | W35: 0.9 | X35: =IFERROR((U35*0.7+T35*0.15+S35*0.15*W40),0) -> 0.96978491 | Y35: =100*(X35-MIN($X$2:$X$692))/(MAX($X$2:$X$692) - MIN($X$2:$X$692)) -> 48.691841 | Z35: =Y35-Q35 -> 45.6556 | AB35: =IFERROR(__xludf.DUMMYFUNCTION("iferror(PERCENTRANK.INC(FILTER($X$2:$X$423, $U$2:$U$423<3.75), $X35), 1)"),0.93) -> 0.93 | AC35: =IFERROR(__xludf.DUMMYFUNCTION("iferror(PERCENTRANK.INC(FILTER($X$2:$X$423, $U$2:$U$423<4.25), $X35), 1)"),0.903) -> 0.903 | AD35: =IFERROR(__xludf.DUMMYFUNCTION("iferror(PERCENTRANK.INC(FILTER($X$2:$X$423, $U$2:$U$423>=4.1), $X35), 0.01)"),0.055) -> 0.055
A36: Ty Simpson | B36: ALABAMA | C36: 15 | D36: QB | E36: SEC | F36: 468 | G36: 413 | H36: 263 | I36: 0.637 | J36: 3129 | K36: 7.6 | L36: 25 | M36: 5 | N36: 23 | O36: 14 | P36: =IFERROR((I36*0.35+K36*7+L36*6+J36/25-M36*10-(N36/F36)*50-(O36/G36)*40)/50,0) -> 5.4953951 | Q36: =100*(P36-MIN($P$2:$P$692))/(MAX($P$2:$P$692) - MIN($P$2:$P$692)) -> 3.004956 | S36: 5.4953951 | T36: 0.95 | W36: 1 | X36: =IFERROR((U36*0.7+T36*0.15+S36*0.15*W41),0) -> 0.96680926 | Y36: =100*(X36-MIN($X$2:$X$692))/(MAX($X$2:$X$692) - MIN($X$2:$X$692)) -> 48.655047 | Z36: =Y36-Q36 -> 45.650091 | AB36: =IFERROR(__xludf.DUMMYFUNCTION("iferror(PERCENTRANK.INC(FILTER($X$2:$X$423, $U$2:$U$423<3.75), $X36), 1)"),0.925) -> 0.925 | AC36: =IFERROR(__xludf.DUMMYFUNCTION("iferror(PERCENTRANK.INC(FILTER($X$2:$X$423, $U$2:$U$423<4.25), $X36), 1)"),0.898) -> 0.898 | AD36: =IFERROR(__xludf.DUMMYFUNCTION("iferror(PERCENTRANK.INC(FILTER($X$2:$X$423, $U$2:$U$423>=4.1), $X36), 0.01)"),0.055) -> 0.055
A37: Byrum Brown | B37: USF | C37: 17 | D37: QB | E37: The American | F37: 431 | G37: 366 | H37: 230 | I37: 0.628 | J37: 3169 | K37: 8.7 | L37: 28 | M37: 9 | N37: 15 | O37: 11 | P37: =IFERROR((I37*0.35+K37*7+L37*6+J37/25-M37*10-(N37/F37)*50-(O37/G37)*40)/50,0) -> 5.2587495 | Q37: =100*(P37-MIN($P$2:$P$692))/(MAX($P$2:$P$692) - MIN($P$2:$P$692)) -> 2.8927387 | S37: 5.2587495 | T37: 1 | W37: 0.95 | X37: =IFERROR((U37*0.7+T37*0.15+S37*0.15*W42),0) -> 0.85993118 | Y37: =100*(X37-MIN($X$2:$X$692))/(MAX($X$2:$X$692) - MIN($X$2:$X$692)) -> 47.333493 | Z37: =Y37-Q37 -> 44.440754 | AB37: =IFERROR(__xludf.DUMMYFUNCTION("iferror(PERCENTRANK.INC(FILTER($X$2:$X$423, $U$2:$U$423<3.75), $X37), 1)"),0.866) -> 0.866 | AC37: =IFERROR(__xludf.DUMMYFUNCTION("iferror(PERCENTRANK.INC(FILTER($X$2:$X$423, $U$2:$U$423<4.25), $X37), 1)"),0.84) -> 0.84 | AD37: =IFERROR(__xludf.DUMMYFUNCTION("iferror(PERCENTRANK.INC(FILTER($X$2:$X$423, $U$2:$U$423>=4.1), $X37), 0.01)"),0.053) -> 0.053
A38: Sawyer Robertson | B38: BAYLOR | C38: 13 | D38: QB | E38: Big 12 | F38: 590 | G38: 548 | H38: 310 | I38: 0.566 | J38: 3724 | K38: 6.8 | L38: 31 | M38: 12 | N38: 21 | O38: 21 | P38: =IFERROR((I38*0.35+K38*7+L38*6+J38/25-M38*10-(N38/F38)*50-(O38/G38)*40)/50,0) -> 5.1889118 | Q38: =100*(P38-MIN($P$2:$P$692))/(MAX($P$2:$P$692) - MIN($P$2:$P$692)) -> 2.8596217 | S38: 5.1889118 | T38: 1.39 | W38: 1 | X38: =IFERROR((U38*0.7+T38*0.15+S38*0.15*W43),0) -> 0.9090031 | Y38: =100*(X38-MIN($X$2:$X$692))/(MAX($X$2:$X$692) - MIN($X$2:$X$692)) -> 47.94027 | Z38: =Y38-Q38 -> 45.080649 | AB38: =IFERROR(__xludf.DUMMYFUNCTION("iferror(PERCENTRANK.INC(FILTER($X$2:$X$423, $U$2:$U$423<3.75), $X38), 1)"),0.902) -> 0.902 | AC38: =IFERROR(__xludf.DUMMYFUNCTION("iferror(PERCENTRANK.INC(FILTER($X$2:$X$423, $U$2:$U$423<4.25), $X38), 1)"),0.875) -> 0.875 | AD38: =IFERROR(__xludf.DUMMYFUNCTION("iferror(PERCENTRANK.INC(FILTER($X$2:$X$423, $U$2:$U$423>=4.1), $X38), 0.01)"),0.054) -> 0.054
A39: Ty Pennington | B39: N ARIZONA | C39: 6 | D39: QB | E39: Big Sky | F39: 438 | G39: 396 | H39: 257 | I39: 0.649 | J39: 3239 | K39: 8.2 | L39: 19 | M39: 4 | N39: 22 | O39: 7 | P39: =IFERROR((I39*0.35+K39*7+L39*6+J39/25-M39*10-(N39/F39)*50-(O39/G39)*40)/50,0) -> 5.1593733 | Q39: =100*(P39-MIN($P$2:$P$692))/(MAX($P$2:$P$692) - MIN($P$2:$P$692)) -> 2.8456145 | S39: 5.1593733 | T39: 3.1 | W39: 0.9 | X39: =IFERROR((U39*0.7+T39*0.15+S39*0.15*W44),0) -> 1.1615154 | Y39: =100*(X39-MIN($X$2:$X$692))/(MAX($X$2:$X$692) - MIN($X$2:$X$692)) -> 51.062601 | Z39: =Y39-Q39 -> 48.216986 | AB39: =IFERROR(__xludf.DUMMYFUNCTION("iferror(PERCENTRANK.INC(FILTER($X$2:$X$423, $U$2:$U$423<3.75), $X39), 1)"),0.948) -> 0.948 | AC39: =IFERROR(__xludf.DUMMYFUNCTION("iferror(PERCENTRANK.INC(FILTER($X$2:$X$423, $U$2:$U$423<4.25), $X39), 1)"),0.92) -> 0.92 | AD39: =IFERROR(__xludf.DUMMYFUNCTION("iferror(PERCENTRANK.INC(FILTER($X$2:$X$423, $U$2:$U$423>=4.1), $X39), 0.01)"),0.058) -> 0.058
A40: Victor Gabalis | B40: TARLETON | C40: 11 | D40: QB | E40: United Athletic | F40: 321 | G40: 287 | H40: 168 | I40: 0.585 | J40: 2596 | K40: 9.1 | L40: 25 | M40: 5 | N40: 19 | O40: 7 | P40: =IFERROR((I40*0.35+K40*7+L40*6+J40/25-M40*10-(N40/F40)*50-(O40/G40)*40)/50,0) -> 5.2761928 | Q40: =100*(P40-MIN($P$2:$P$692))/(MAX($P$2:$P$692) - MIN($P$2:$P$692)) -> 2.9010103 | S40: 5.2761928 | T40: 0.68 | W40: 0.9 | X40: =IFERROR((U40*0.7+T40*0.15+S40*0.15*W45),0) -> 0.81428602 | Y40: =100*(X40-MIN($X$2:$X$692))/(MAX($X$2:$X$692) - MIN($X$2:$X$692)) -> 46.769088 | Z40: =Y40-Q40 -> 43.868077 | AB40: =IFERROR(__xludf.DUMMYFUNCTION("iferror(PERCENTRANK.INC(FILTER($X$2:$X$423, $U$2:$U$423<3.75), $X40), 1)"),0.835) -> 0.835 | AC40: =IFERROR(__xludf.DUMMYFUNCTION("iferror(PERCENTRANK.INC(FILTER($X$2:$X$423, $U$2:$U$423<4.25), $X40), 1)"),0.81) -> 0.81 | AD40: =IFERROR(__xludf.DUMMYFUNCTION("iferror(PERCENTRANK.INC(FILTER($X$2:$X$423, $U$2:$U$423>=4.1), $X40), 0.01)"),0.053) -> 0.053
...

Sheet RB Sheet
A1: Name | B1: Team | C1: # | D1: POS | E1: CONF | F1: ATT | G1: RUN YDS | H1: YPC | I1: RUN TD | J1: Game Score | K1: Normalized Score | M1: Game Score | N1: Average Value | O1: Film Grade | P1: Production Modifier | Q1: Adjusted Score | R1: Normalized Score | T1: FCS Prospect Percentile | U1: G5 Prospect Percentile | V1: P4 Prospect Percentile
A2: Xai'Shaun Edwards | B2: HOUCHR | C2: 24 | D2: HB | E2: Southland | F2: 161 | G2: 878 | H2: 5.5 | I2: 10 | J2: 4.802 | K2: =100*(J2-MIN($J$2:$J$143))/(MAX($J$2:$J$143) - MIN($J$2:$J$143)) -> 48.328817 | M2: 4.802 | N2: 8.9 | O2: 5.34 | P2: 0.9 | Q2: =IFERROR(M2*P2*0.05+N2*0.05+O2*0.9,0) -> 5.46709 | R2: =100*(Q2-MIN($Q$2:$Q$143))/(MAX($Q$2:$Q$143) - MIN($Q$2:$Q$143)) -> 100 | T2: =IFERROR(__xludf.DUMMYFUNCTION("iferror(PERCENTRANK.INC(FILTER($Q$2:$Q$428, $O$2:$O$428<3.75), $Q2), 1)"),1.0) -> 1 | U2: =IFERROR(__xludf.DUMMYFUNCTION("iferror(PERCENTRANK.INC(FILTER($Q$2:$Q$428, $O$2:$O$428<4.25), $Q2), 1)"),1.0) -> 1 | V2: =IFERROR(__xludf.DUMMYFUNCTION("iferror(PERCENTRANK.INC(FILTER($Q$2:$Q$428, $O$2:$O$428>=4.1), $Q2), 0.01)"),1.0) -> 1
A3: Miles Davis | B3: UTAH ST | C3: 2 | D3: HB | E3: MWC | F3: 99 | G3: 623 | H3: 6.3 | I3: 6 | J3: 3.568 | K3: =100*(J3-MIN($J$2:$J$143))/(MAX($J$2:$J$143) - MIN($J$2:$J$143)) -> 29.750075 | M3: 3.568 | N3: 1.05 | O3: 5.66 | P3: 0.95 | Q3: =IFERROR(M3*P3*0.05+N3*0.05+O3*0.9,0) -> 5.31598 | R3: =100*(Q3-MIN($Q$2:$Q$143))/(MAX($Q$2:$Q$143) - MIN($Q$2:$Q$143)) -> 97.236007 | T3: =IFERROR(__xludf.DUMMYFUNCTION("iferror(PERCENTRANK.INC(FILTER($Q$2:$Q$428, $O$2:$O$428<3.75), $Q3), 1)"),1.0) -> 1 | U3: =IFERROR(__xludf.DUMMYFUNCTION("iferror(PERCENTRANK.INC(FILTER($Q$2:$Q$428, $O$2:$O$428<4.25), $Q3), 1)"),1.0) -> 1 | V3: =IFERROR(__xludf.DUMMYFUNCTION("iferror(PERCENTRANK.INC(FILTER($Q$2:$Q$428, $O$2:$O$428>=4.1), $Q3), 0.01)"),0.973) -> 0.973
A4: Dason Brooks | B4: IDAHO ST | C4: 28 | D4: HB | E4: Big Sky | F4: 127 | G4: 905 | H4: 7.1 | I4: 9 | J4: 4.788 | K4: =100*(J4-MIN($J$2:$J$143))/(MAX($J$2:$J$143) - MIN($J$2:$J$143)) -> 48.118037 | M4: 4.788 | N4: 3.3 | O4: 5.28 | P4: 0.9 | Q4: =IFERROR(M4*P4*0.05+N4*0.05+O4*0.9,0) -> 5.13246 | R4: =100*(Q4-MIN($Q$2:$Q$143))/(MAX($Q$2:$Q$143) - MIN($Q$2:$Q$143)) -> 93.879193 | T4: =IFERROR(__xludf.DUMMYFUNCTION("iferror(PERCENTRANK.INC(FILTER($Q$2:$Q$428, $O$2:$O$428<3.75), $Q4), 1)"),1.0) -> 1 | U4: =IFERROR(__xludf.DUMMYFUNCTION("iferror(PERCENTRANK.INC(FILTER($Q$2:$Q$428, $O$2:$O$428<4.25), $Q4), 1)"),1.0) -> 1 | V4: =IFERROR(__xludf.DUMMYFUNCTION("iferror(PERCENTRANK.INC(FILTER($Q$2:$Q$428, $O$2:$O$428>=4.1), $Q4), 0.01)"),0.946) -> 0.946
A5: Cam Cook | B5: JVILLE ST | C5: 4 | D5: HB | E5: C-USA | F5: 206 | G5: 1192 | H5: 5.8 | I5: 12 | J5: 5.988 | K5: =100*(J5-MIN($J$2:$J$143))/(MAX($J$2:$J$143) - MIN($J$2:$J$143)) -> 66.184884 | M5: 5.988 | N5: 0.78 | O5: 5.34 | P5: 0.95 | Q5: =IFERROR(M5*P5*0.05+N5*0.05+O5*0.9,0) -> 5.12943 | R5: =100*(Q5-MIN($Q$2:$Q$143))/(MAX($Q$2:$Q$143) - MIN($Q$2:$Q$143)) -> 93.823771 | T5: =IFERROR(__xludf.DUMMYFUNCTION("iferror(PERCENTRANK.INC(FILTER($Q$2:$Q$428, $O$2:$O$428<3.75), $Q5), 1)"),1.0) -> 1 | U5: =IFERROR(__xludf.DUMMYFUNCTION("iferror(PERCENTRANK.INC(FILTER($Q$2:$Q$428, $O$2:$O$428<4.25), $Q5), 1)"),1.0) -> 1 | V5: =IFERROR(__xludf.DUMMYFUNCTION("iferror(PERCENTRANK.INC(FILTER($Q$2:$Q$428, $O$2:$O$428>=4.1), $Q5), 0.01)"),0.919) -> 0.919
A6: Carson Gresock | B6: GARD-WEBB | C6: 33 | D6: HB | E6: Big South - OVC Football Association | F6: 99 | G6: 707 | H6: 7.1 | I6: 12 | J6: 4.584 | K6: =100*(J6-MIN($J$2:$J$143))/(MAX($J$2:$J$143) - MIN($J$2:$J$143)) -> 45.046673 | M6: 4.584 | N6: 5.9 | O6: 5.02 | P6: 0.9 | Q6: =IFERROR(M6*P6*0.05+N6*0.05+O6*0.9,0) -> 5.01928 | R6: =100*(Q6-MIN($Q$2:$Q$143))/(MAX($Q$2:$Q$143) - MIN($Q$2:$Q$143)) -> 91.808988 | T6: =IFERROR(__xludf.DUMMYFUNCTION("iferror(PERCENTRANK.INC(FILTER($Q$2:$Q$428, $O$2:$O$428<3.75), $Q6), 1)"),1.0) -> 1 | U6: =IFERROR(__xludf.DUMMYFUNCTION("iferror(PERCENTRANK.INC(FILTER($Q$2:$Q$428, $O$2:$O$428<4.25), $Q6), 1)"),1.0) -> 1 | V6: =IFERROR(__xludf.DUMMYFUNCTION("iferror(PERCENTRANK.INC(FILTER($Q$2:$Q$428, $O$2:$O$428>=4.1), $Q6), 0.01)"),0.838) -> 0.838
A7: Nykahi Davenport | B7: USF | C7: 25 | D7: HB | E7: The American | F7: 55 | G7: 396 | H7: 7.2 | I7: 5 | J7: 2.874 | K7: =100*(J7-MIN($J$2:$J$143))/(MAX($J$2:$J$143) - MIN($J$2:$J$143)) -> 19.301415 | M7: 2.874 | N7: 0.78 | O7: 5.34 | P7: 0.95 | Q7: =IFERROR(M7*P7*0.05+N7*0.05+O7*0.9,0) -> 4.981515 | R7: =100*(Q7-MIN($Q$2:$Q$143))/(MAX($Q$2:$Q$143) - MIN($Q$2:$Q$143)) -> 91.118218 | T7: =IFERROR(__xludf.DUMMYFUNCTION("iferror(PERCENTRANK.INC(FILTER($Q$2:$Q$428, $O$2:$O$428<3.75), $Q7), 1)"),1.0) -> 1 | U7: =IFERROR(__xludf.DUMMYFUNCTION("iferror(PERCENTRANK.INC(FILTER($Q$2:$Q$428, $O$2:$O$428<4.25), $Q7), 1)"),1.0) -> 1 | V7: =IFERROR(__xludf.DUMMYFUNCTION("iferror(PERCENTRANK.INC(FILTER($Q$2:$Q$428, $O$2:$O$428>=4.1), $Q7), 0.01)"),0.784) -> 0.784
A8: Ofa Mataele | B8: W MICHIGAN | C8: 24 | D8: HB | E8: MAC | F8: 40 | G8: 187 | H8: 4.7 | I8: 3 | J8: 1.726 | K8: =100*(J8-MIN($J$2:$J$143))/(MAX($J$2:$J$143) - MIN($J$2:$J$143)) -> 2.0174646 | M8: 1.726 | N8: 6.47 | O8: 4.96 | P8: 0.95 | Q8: =IFERROR(M8*P8*0.05+N8*0.05+O8*0.9,0) -> 4.869485 | R8: =100*(Q8-MIN($Q$2:$Q$143))/(MAX($Q$2:$Q$143) - MIN($Q$2:$Q$143)) -> 89.069048 | T8: =IFERROR(__xludf.DUMMYFUNCTION("iferror(PERCENTRANK.INC(FILTER($Q$2:$Q$428, $O$2:$O$428<3.75), $Q8), 1)"),1.0) -> 1 | U8: =IFERROR(__xludf.DUMMYFUNCTION("iferror(PERCENTRANK.INC(FILTER($Q$2:$Q$428, $O$2:$O$428<4.25), $Q8), 1)"),1.0) -> 1 | V8: =IFERROR(__xludf.DUMMYFUNCTION("iferror(PERCENTRANK.INC(FILTER($Q$2:$Q$428, $O$2:$O$428>=4.1), $Q8), 0.01)"),0.73) -> 0.73
A9: Daelen Alexander | B9: RICE | C9: 20 | D9: HB | E9: The American | F9: 74 | G9: 392 | H9: 5.3 | I9: 3 | J9: 2.436 | K9: =100*(J9-MIN($J$2:$J$143))/(MAX($J$2:$J$143) - MIN($J$2:$J$143)) -> 12.707016 | M9: 2.436 | N9: 10 | O9: 4.67 | P9: 0.95 | Q9: =IFERROR(M9*P9*0.05+N9*0.05+O9*0.9,0) -> 4.81871 | R9: =100*(Q9-MIN($Q$2:$Q$143))/(MAX($Q$2:$Q$143) - MIN($Q$2:$Q$143)) -> 88.140309 | T9: =IFERROR(__xludf.DUMMYFUNCTION("iferror(PERCENTRANK.INC(FILTER($Q$2:$Q$428, $O$2:$O$428<3.75), $Q9), 1)"),1.0) -> 1 | U9: =IFERROR(__xludf.DUMMYFUNCTION("iferror(PERCENTRANK.INC(FILTER($Q$2:$Q$428, $O$2:$O$428<4.25), $Q9), 1)"),1.0) -> 1 | V9: =IFERROR(__xludf.DUMMYFUNCTION("iferror(PERCENTRANK.INC(FILTER($Q$2:$Q$428, $O$2:$O$428>=4.1), $Q9), 0.01)"),0.703) -> 0.703
A10: Cornell Hatcher Jr. | B10: OREGON ST | C10: 21 | D10: HB | E10: Pac-12 | F10: 45 | G10: 262 | H10: 5.8 | I10: 2 | J10: 1.962 | K10: =100*(J10-MIN($J$2:$J$143))/(MAX($J$2:$J$143) - MIN($J$2:$J$143)) -> 5.5706113 | M10: 1.962 | N10: 7.56 | O10: 4.7 | P10: 0.95 | Q10: =IFERROR(M10*P10*0.05+N10*0.05+O10*0.9,0) -> 4.701195 | R10: =100*(Q10-MIN($Q$2:$Q$143))/(MAX($Q$2:$Q$143) - MIN($Q$2:$Q$143)) -> 85.99081 | T10: =IFERROR(__xludf.DUMMYFUNCTION("iferror(PERCENTRANK.INC(FILTER($Q$2:$Q$428, $O$2:$O$428<3.75), $Q10), 1)"),1.0) -> 1 | U10: =IFERROR(__xludf.DUMMYFUNCTION("iferror(PERCENTRANK.INC(FILTER($Q$2:$Q$428, $O$2:$O$428<4.25), $Q10), 1)"),1.0) -> 1 | V10: =IFERROR(__xludf.DUMMYFUNCTION("iferror(PERCENTRANK.INC(FILTER($Q$2:$Q$428, $O$2:$O$428>=4.1), $Q10), 0.01)"),0.649) -> 0.649
A11: Jeffery Pittman | B11: SO MISS | C11: 0 | D11: HB | E11: Sun Belt | F11: 118 | G11: 525 | H11: 4.5 | I11: 6 | J11: 3.198 | K11: =100*(J11-MIN($J$2:$J$143))/(MAX($J$2:$J$143) - MIN($J$2:$J$143)) -> 24.179464 | M11: 3.198 | N11: 4.94 | O11: 4.7 | P11: 0.95 | Q11: =IFERROR(M11*P11*0.05+N11*0.05+O11*0.9,0) -> 4.628905 | R11: =100*(Q11-MIN($Q$2:$Q$143))/(MAX($Q$2:$Q$143) - MIN($Q$2:$Q$143)) -> 84.668535 | T11: =IFERROR(__xludf.DUMMYFUNCTION("iferror(PERCENTRANK.INC(FILTER($Q$2:$Q$428, $O$2:$O$428<3.75), $Q11), 1)"),1.0) -> 1 | U11: =IFERROR(__xludf.DUMMYFUNCTION("iferror(PERCENTRANK.INC(FILTER($Q$2:$Q$428, $O$2:$O$428<4.25), $Q11), 1)"),1.0) -> 1 | V11: =IFERROR(__xludf.DUMMYFUNCTION("iferror(PERCENTRANK.INC(FILTER($Q$2:$Q$428, $O$2:$O$428>=4.1), $Q11), 0.01)"),0.595) -> 0.595
A12: Brady Hensley | B12: E KENTUCKY | C12: 42 | D12: HB | E12: United Athletic | F12: 76 | G12: 478 | H12: 6.3 | I12: 4 | J12: 2.9 | K12: =100*(J12-MIN($J$2:$J$143))/(MAX($J$2:$J$143) - MIN($J$2:$J$143)) -> 19.692864 | M12: 2.9 | N12: 10 | O12: 4.38 | P12: 0.9 | Q12: =IFERROR(M12*P12*0.05+N12*0.05+O12*0.9,0) -> 4.5725 | R12: =100*(Q12-MIN($Q$2:$Q$143))/(MAX($Q$2:$Q$143) - MIN($Q$2:$Q$143)) -> 83.636816 | T12: =IFERROR(__xludf.DUMMYFUNCTION("iferror(PERCENTRANK.INC(FILTER($Q$2:$Q$428, $O$2:$O$428<3.75), $Q12), 1)"),1.0) -> 1 | U12: =IFERROR(__xludf.DUMMYFUNCTION("iferror(PERCENTRANK.INC(FILTER($Q$2:$Q$428, $O$2:$O$428<4.25), $Q12), 1)"),1.0) -> 1 | V12: =IFERROR(__xludf.DUMMYFUNCTION("iferror(PERCENTRANK.INC(FILTER($Q$2:$Q$428, $O$2:$O$428>=4.1), $Q12), 0.01)"),0.568) -> 0.568
A13: Caleb Hawkins | B13: N TEXAS | C13: 24 | D13: HB | E13: The American | F13: 124 | G13: 760 | H13: 6.1 | I13: 11 | J13: 4.56 | K13: =100*(J13-MIN($J$2:$J$143))/(MAX($J$2:$J$143) - MIN($J$2:$J$143)) -> 44.685336 | M13: 4.56 | N13: 0.69 | O13: 4.7 | P13: 0.95 | Q13: =IFERROR(M13*P13*0.05+N13*0.05+O13*0.9,0) -> 4.4811 | R13: =100*(Q13-MIN($Q$2:$Q$143))/(MAX($Q$2:$Q$143) - MIN($Q$2:$Q$143)) -> 81.964994 | T13: =IFERROR(__xludf.DUMMYFUNCTION("iferror(PERCENTRANK.INC(FILTER($Q$2:$Q$428, $O$2:$O$428<3.75), $Q13), 1)"),1.0) -> 1 | U13: =IFERROR(__xludf.DUMMYFUNCTION("iferror(PERCENTRANK.INC(FILTER($Q$2:$Q$428, $O$2:$O$428<4.25), $Q13), 1)"),1.0) -> 1 | V13: =IFERROR(__xludf.DUMMYFUNCTION("iferror(PERCENTRANK.INC(FILTER($Q$2:$Q$428, $O$2:$O$428>=4.1), $Q13), 0.01)"),0.541) -> 0.541
A14: Telly Johnson Jr. | B14: N ILLINOIS | C14: 45 | D14: HB | E14: MAC | F14: 103 | G14: 597 | H14: 5.8 | I14: 3 | J14: 3.1 | K14: =100*(J14-MIN($J$2:$J$143))/(MAX($J$2:$J$143) - MIN($J$2:$J$143)) -> 22.704005 | M14: 3.1 | N14: 0.81 | O14: 4.75 | P14: 0.95 | Q14: =IFERROR(M14*P14*0.05+N14*0.05+O14*0.9,0) -> 4.46275 | R14: =100*(Q14-MIN($Q$2:$Q$143))/(MAX($Q$2:$Q$143) - MIN($Q$2:$Q$143)) -> 81.629349 | T14: =IFERROR(__xludf.DUMMYFUNCTION("iferror(PERCENTRANK.INC(FILTER($Q$2:$Q$428, $O$2:$O$428<3.75), $Q14), 1)"),1.0) -> 1 | U14: =IFERROR(__xludf.DUMMYFUNCTION("iferror(PERCENTRANK.INC(FILTER($Q$2:$Q$428, $O$2:$O$428<4.25), $Q14), 1)"),1.0) -> 1 | V14: =IFERROR(__xludf.DUMMYFUNCTION("iferror(PERCENTRANK.INC(FILTER($Q$2:$Q$428, $O$2:$O$428>=4.1), $Q14), 0.01)"),0.486) -> 0.486
A15: Zylan Perry | B15: LA LAFAYET | C15: 3 | D15: HB | E15: Sun Belt | F15: 112 | G15: 611 | H15: 5.5 | I15: 7 | J15: 3.614 | K15: =100*(J15-MIN($J$2:$J$143))/(MAX($J$2:$J$143) - MIN($J$2:$J$143)) -> 30.442638 | M15: 3.614 | N15: 0.89 | O15: 4.64 | P15: 0.95 | Q15: =IFERROR(M15*P15*0.05+N15*0.05+O15*0.9,0) -> 4.392165 | R15: =100*(Q15-MIN($Q$2:$Q$143))/(MAX($Q$2:$Q$143) - MIN($Q$2:$Q$143)) -> 80.33826 | T15: =IFERROR(__xludf.DUMMYFUNCTION("iferror(PERCENTRANK.INC(FILTER($Q$2:$Q$428, $O$2:$O$428<3.75), $Q15), 1)"),1.0) -> 1 | U15: =IFERROR(__xludf.DUMMYFUNCTION("iferror(PERCENTRANK.INC(FILTER($Q$2:$Q$428, $O$2:$O$428<4.25), $Q15), 1)"),1.0) -> 1 | V15: =IFERROR(__xludf.DUMMYFUNCTION("iferror(PERCENTRANK.INC(FILTER($Q$2:$Q$428, $O$2:$O$428>=4.1), $Q15), 0.01)"),0.432) -> 0.432
A16: Dominic Knicely | B16: COAST CAR | C16: 23 | D16: HB | E16: Sun Belt | F16: 56 | G16: 363 | H16: 6.5 | I16: 2 | J16: 2.342 | K16: =100*(J16-MIN($J$2:$J$143))/(MAX($J$2:$J$143) - MIN($J$2:$J$143)) -> 11.29178 | M16: 2.342 | N16: 1 | O16: 4.7 | P16: 0.95 | Q16: =IFERROR(M16*P16*0.05+N16*0.05+O16*0.9,0) -> 4.391245 | R16: =100*(Q16-MIN($Q$2:$Q$143))/(MAX($Q$2:$Q$143) - MIN($Q$2:$Q$143)) -> 80.321432 | T16: =IFERROR(__xludf.DUMMYFUNCTION("iferror(PERCENTRANK.INC(FILTER($Q$2:$Q$428, $O$2:$O$428<3.75), $Q16), 1)"),1.0) -> 1 | U16: =IFERROR(__xludf.DUMMYFUNCTION("iferror(PERCENTRANK.INC(FILTER($Q$2:$Q$428, $O$2:$O$428<4.25), $Q16), 1)"),1.0) -> 1 | V16: =IFERROR(__xludf.DUMMYFUNCTION("iferror(PERCENTRANK.INC(FILTER($Q$2:$Q$428, $O$2:$O$428>=4.1), $Q16), 0.01)"),0.405) -> 0.405
A17: Greg Burrell | B17: TEXAS ST | C17: 9 | D17: HB | E17: Sun Belt | F17: 64 | G17: 394 | H17: 6.2 | I17: 3 | J17: 2.524 | K17: =100*(J17-MIN($J$2:$J$143))/(MAX($J$2:$J$143) - MIN($J$2:$J$143)) -> 14.031918 | M17: 2.524 | N17: 0.06 | O17: 4.7 | P17: 0.95 | Q17: =IFERROR(M17*P17*0.05+N17*0.05+O17*0.9,0) -> 4.35289 | R17: =100*(Q17-MIN($Q$2:$Q$143))/(MAX($Q$2:$Q$143) - MIN($Q$2:$Q$143)) -> 79.619871 | T17: =IFERROR(__xludf.DUMMYFUNCTION("iferror(PERCENTRANK.INC(FILTER($Q$2:$Q$428, $O$2:$O$428<3.75), $Q17), 1)"),1.0) -> 1 | U17: =IFERROR(__xludf.DUMMYFUNCTION("iferror(PERCENTRANK.INC(FILTER($Q$2:$Q$428, $O$2:$O$428<4.25), $Q17), 1)"),1.0) -> 1 | V17: =IFERROR(__xludf.DUMMYFUNCTION("iferror(PERCENTRANK.INC(FILTER($Q$2:$Q$428, $O$2:$O$428>=4.1), $Q17), 0.01)"),0.351) -> 0.351
A18: Jaylen Jennings | B18: ARKAPB | C18: 25 | D18: HB | E18: SWAC | F18: 136 | G18: 688 | H18: 5.1 | I18: 9 | J18: 4.088 | K18: =100*(J18-MIN($J$2:$J$143))/(MAX($J$2:$J$143) - MIN($J$2:$J$143)) -> 37.579042 | M18: 4.088 | N18: 10 | O18: 4.05 | P18: 0.9 | Q18: =IFERROR(M18*P18*0.05+N18*0.05+O18*0.9,0) -> 4.32896 | R18: =100*(Q18-MIN($Q$2:$Q$143))/(MAX($Q$2:$Q$143) - MIN($Q$2:$Q$143)) -> 79.182161 | T18: =IFERROR(__xludf.DUMMYFUNCTION("iferror(PERCENTRANK.INC(FILTER($Q$2:$Q$428, $O$2:$O$428<3.75), $Q18), 1)"),1.0) -> 1 | U18: =IFERROR(__xludf.DUMMYFUNCTION("iferror(PERCENTRANK.INC(FILTER($Q$2:$Q$428, $O$2:$O$428<4.25), $Q18), 1)"),1.0) -> 1 | V18: =IFERROR(__xludf.DUMMYFUNCTION("iferror(PERCENTRANK.INC(FILTER($Q$2:$Q$428, $O$2:$O$428>=4.1), $Q18), 0.01)"),0.339) -> 0.339
A19: Lucky Sutton | B19: S DIEGO ST | C19: 7 | D19: HB | E19: MWC | F19: 173 | G19: 901 | H19: 5.2 | I19: 8 | J19: 4.632 | K19: =100*(J19-MIN($J$2:$J$143))/(MAX($J$2:$J$143) - MIN($J$2:$J$143)) -> 45.769347 | M19: 4.632 | N19: 2.77 | O19: 4.38 | P19: 0.95 | Q19: =IFERROR(M19*P19*0.05+N19*0.05+O19*0.9,0) -> 4.30052 | R19: =100*(Q19-MIN($Q$2:$Q$143))/(MAX($Q$2:$Q$143) - MIN($Q$2:$Q$143)) -> 78.661957 | T19: =IFERROR(__xludf.DUMMYFUNCTION("iferror(PERCENTRANK.INC(FILTER($Q$2:$Q$428, $O$2:$O$428<3.75), $Q19), 1)"),1.0) -> 1 | U19: =IFERROR(__xludf.DUMMYFUNCTION("iferror(PERCENTRANK.INC(FILTER($Q$2:$Q$428, $O$2:$O$428<4.25), $Q19), 1)"),0.999) -> 0.999 | V19: =IFERROR(__xludf.DUMMYFUNCTION("iferror(PERCENTRANK.INC(FILTER($Q$2:$Q$428, $O$2:$O$428>=4.1), $Q19), 0.01)"),0.324) -> 0.324
A20: Landan Brown | B20: SM HOUSTON | C20: 34 | D20: HB | E20: C-USA | F20: 59 | G20: 302 | H20: 5.1 | I20: 2 | J20: 2.014 | K20: =100*(J20-MIN($J$2:$J$143))/(MAX($J$2:$J$143) - MIN($J$2:$J$143)) -> 6.353508 | M20: 2.014 | N20: 5.41 | O20: 4.32 | P20: 0.95 | Q20: =IFERROR(M20*P20*0.05+N20*0.05+O20*0.9,0) -> 4.254165 | R20: =100*(Q20-MIN($Q$2:$Q$143))/(MAX($Q$2:$Q$143) - MIN($Q$2:$Q$143)) -> 77.814066 | T20: =IFERROR(__xludf.DUMMYFUNCTION("iferror(PERCENTRANK.INC(FILTER($Q$2:$Q$428, $O$2:$O$428<3.75), $Q20), 1)"),1.0) -> 1 | U20: =IFERROR(__xludf.DUMMYFUNCTION("iferror(PERCENTRANK.INC(FILTER($Q$2:$Q$428, $O$2:$O$428<4.25), $Q20), 1)"),0.997) -> 0.997 | V20: =IFERROR(__xludf.DUMMYFUNCTION("iferror(PERCENTRANK.INC(FILTER($Q$2:$Q$428, $O$2:$O$428>=4.1), $Q20), 0.01)"),0.297) -> 0.297
A21: Nick Herman | B21: DRAKE | C21: 29 | D21: HB | E21: Pioneer | F21: 88 | G21: 558 | H21: 6.3 | I21: 4 | J21: 3.132 | K21: =100*(J21-MIN($J$2:$J$143))/(MAX($J$2:$J$143) - MIN($J$2:$J$143)) -> 23.185787 | M21: 3.132 | N21: 3.12 | O21: 4.38 | P21: 0.9 | Q21: =IFERROR(M21*P21*0.05+N21*0.05+O21*0.9,0) -> 4.23894 | R21: =100*(Q21-MIN($Q$2:$Q$143))/(MAX($Q$2:$Q$143) - MIN($Q$2:$Q$143)) -> 77.535581 | T21: =IFERROR(__xludf.DUMMYFUNCTION("iferror(PERCENTRANK.INC(FILTER($Q$2:$Q$428, $O$2:$O$428<3.75), $Q21), 1)"),1.0) -> 1 | U21: =IFERROR(__xludf.DUMMYFUNCTION("iferror(PERCENTRANK.INC(FILTER($Q$2:$Q$428, $O$2:$O$428<4.25), $Q21), 1)"),0.997) -> 0.997 | V21: =IFERROR(__xludf.DUMMYFUNCTION("iferror(PERCENTRANK.INC(FILTER($Q$2:$Q$428, $O$2:$O$428>=4.1), $Q21), 0.01)"),0.27) -> 0.27
A22: Terron Kellman | B22: WYOMING | C22: 5 | D22: HB | E22: MWC | F22: 62 | G22: 326 | H22: 5.3 | I22: 4 | J22: 2.352 | K22: =100*(J22-MIN($J$2:$J$143))/(MAX($J$2:$J$143) - MIN($J$2:$J$143)) -> 11.442337 | M22: 2.352 | N22: 3.56 | O22: 4.38 | P22: 0.95 | Q22: =IFERROR(M22*P22*0.05+N22*0.05+O22*0.9,0) -> 4.23172 | R22: =100*(Q22-MIN($Q$2:$Q$143))/(MAX($Q$2:$Q$143) - MIN($Q$2:$Q$143)) -> 77.403518 | T22: =IFERROR(__xludf.DUMMYFUNCTION("iferror(PERCENTRANK.INC(FILTER($Q$2:$Q$428, $O$2:$O$428<3.75), $Q22), 1)"),1.0) -> 1 | U22: =IFERROR(__xludf.DUMMYFUNCTION("iferror(PERCENTRANK.INC(FILTER($Q$2:$Q$428, $O$2:$O$428<4.25), $Q22), 1)"),0.996) -> 0.996 | V22: =IFERROR(__xludf.DUMMYFUNCTION("iferror(PERCENTRANK.INC(FILTER($Q$2:$Q$428, $O$2:$O$428>=4.1), $Q22), 0.01)"),0.243) -> 0.243
A23: Gerald Modest | B23: WOFFORD | C23: 6 | D23: HB | E23: Southern | F23: 97 | G23: 410 | H23: 4.2 | I23: 2 | J23: 2.314 | K23: =100*(J23-MIN($J$2:$J$143))/(MAX($J$2:$J$143) - MIN($J$2:$J$143)) -> 10.87022 | M23: 2.31 | N23: 1.65 | O23: 3.41 | P23: 0.95 | Q23: =IFERROR(M23*P23*0.05+N23*0.05+O23*0.9,0) -> 3.261225 | R23: =100*(Q23-MIN($Q$2:$Q$143))/(MAX($Q$2:$Q$143) - MIN($Q$2:$Q$143)) -> 59.651935 | T23: =IFERROR(__xludf.DUMMYFUNCTION("iferror(PERCENTRANK.INC(FILTER($Q$2:$Q$428, $O$2:$O$428<3.75), $Q23), 1)"),0.922) -> 0.922 | U23: =IFERROR(__xludf.DUMMYFUNCTION("iferror(PERCENTRANK.INC(FILTER($Q$2:$Q$428, $O$2:$O$428<4.25), $Q23), 1)"),0.806) -> 0.806 | V23: =IFERROR(__xludf.DUMMYFUNCTION("iferror(PERCENTRANK.INC(FILTER($Q$2:$Q$428, $O$2:$O$428>=4.1), $Q23), 0.01)"),0.021) -> 0.021
A24: Rayshon Luke | B24: FRESNO ST | C24: 2 | D24: HB | E24: MWC | F24: 84 | G24: 525 | H24: 6.3 | I24: 5 | J24: 3.162 | K24: =100*(J24-MIN($J$2:$J$143))/(MAX($J$2:$J$143) - MIN($J$2:$J$143)) -> 23.637459 | M24: 3.162 | N24: 1.86 | O24: 4.43 | P24: 0.95 | Q24: =IFERROR(M24*P24*0.05+N24*0.05+O24*0.9,0) -> 4.230195 | R24: =100*(Q24-MIN($Q$2:$Q$143))/(MAX($Q$2:$Q$143) - MIN($Q$2:$Q$143)) -> 77.375624 | T24: =IFERROR(__xludf.DUMMYFUNCTION("iferror(PERCENTRANK.INC(FILTER($Q$2:$Q$428, $O$2:$O$428<3.75), $Q24), 1)"),1.0) -> 1 | U24: =IFERROR(__xludf.DUMMYFUNCTION("iferror(PERCENTRANK.INC(FILTER($Q$2:$Q$428, $O$2:$O$428<4.25), $Q24), 1)"),0.996) -> 0.996 | V24: =IFERROR(__xludf.DUMMYFUNCTION("iferror(PERCENTRANK.INC(FILTER($Q$2:$Q$428, $O$2:$O$428>=4.1), $Q24), 0.01)"),0.216) -> 0.216
A25: Clay Thevenin | B25: LA TECH | C25: 4 | D25: HB | E25: C-USA | F25: 97 | G25: 525 | H25: 5.4 | I25: 8 | J25: 3.456 | K25: =100*(J25-MIN($J$2:$J$143))/(MAX($J$2:$J$143) - MIN($J$2:$J$143)) -> 28.063836 | M25: 3.456 | N25: 1.92 | O25: 4.38 | P25: 0.95 | Q25: =IFERROR(M25*P25*0.05+N25*0.05+O25*0.9,0) -> 4.20216 | R25: =100*(Q25-MIN($Q$2:$Q$143))/(MAX($Q$2:$Q$143) - MIN($Q$2:$Q$143)) -> 76.862828 | T25: =IFERROR(__xludf.DUMMYFUNCTION("iferror(PERCENTRANK.INC(FILTER($Q$2:$Q$428, $O$2:$O$428<3.75), $Q25), 1)"),1.0) -> 1 | U25: =IFERROR(__xludf.DUMMYFUNCTION("iferror(PERCENTRANK.INC(FILTER($Q$2:$Q$428, $O$2:$O$428<4.25), $Q25), 1)"),0.995) -> 0.995 | V25: =IFERROR(__xludf.DUMMYFUNCTION("iferror(PERCENTRANK.INC(FILTER($Q$2:$Q$428, $O$2:$O$428>=4.1), $Q25), 0.01)"),0.189) -> 0.189
